Traceback (most recent call last):
  File "AR2.py", line 77, in <module>
  File "Tkinter.pyo", line 1693, in wm_iconbitmap
_tkinter.TclError: bitmap "AR2.ico" not defined
Traceback (most recent call last):
  File "AR2.py", line 62, in <module>
  File "Tkinter.pyo", line 38, in <module>
  File "FixTk.pyo", line 68, in <module>
  File "_tkinter.pyo", line 12, in <module>
  File "_tkinter.pyo", line 10, in __load
ImportError: DLL load failed: The specified module could not be found.
Exception in Tkinter callback
Traceback (most recent call last):
  File "Tkinter.pyo", line 1536, in __call__
  File "AR2.py", line 1498, in J1jogPos
NameError: global name 'ser' is not defined
Exception in Tkinter callback
Traceback (most recent call last):
  File "Tkinter.pyo", line 1536, in __call__
  File "AR2.py", line 1498, in J1jogPos
NameError: global name 'ser' is not defined
Exception in Tkinter callback
Traceback (most recent call last):
  File "Tkinter.pyo", line 1536, in __call__
  File "AR2.py", line 1498, in J1jogPos
NameError: global name 'ser' is not defined
Exception in Tkinter callback
Traceback (most recent call last):
  File "Tkinter.pyo", line 1536, in __call__
  File "AR2.py", line 1498, in J1jogPos
NameError: global name 'ser' is not defined
Exception in Tkinter callback
Traceback (most recent call last):
  File "Tkinter.pyo", line 1536, in __call__
  File "AR2.py", line 1457, in J1jogNeg
NameError: global name 'ser' is not defined
Exception in Tkinter callback
Traceback (most recent call last):
  File "Tkinter.pyo", line 1536, in __call__
  File "AR2.py", line 1457, in J1jogNeg
NameError: global name 'ser' is not defined
Exception in Tkinter callback
Traceback (most recent call last):
  File "Tkinter.pyo", line 1536, in __call__
  File "AR2.py", line 1457, in J1jogNeg
NameError: global name 'ser' is not defined
Exception in Tkinter callback
Traceback (most recent call last):
  File "Tkinter.pyo", line 1536, in __call__
  File "AR2.py", line 1457, in J1jogNeg
NameError: global name 'ser' is not defined
Exception in Tkinter callback
Traceback (most recent call last):
  File "Tkinter.pyo", line 1536, in __call__
  File "AR2.py", line 1457, in J1jogNeg
NameError: global name 'ser' is not defined
Exception in Tkinter callback
Traceback (most recent call last):
  File "Tkinter.pyo", line 1536, in __call__
  File "AR2.py", line 768, in calRobotAll
  File "AR2.py", line 957, in calRobot
NameError: global name 'ser' is not defined
Exception in Tkinter callback
Traceback (most recent call last):
  File "Tkinter.pyo", line 1536, in __call__
  File "AR2.py", line 768, in calRobotAll
  File "AR2.py", line 957, in calRobot
NameError: global name 'ser' is not defined
Exception in thread Thread-1:
Traceback (most recent call last):
  File "threading.pyo", line 801, in __bootstrap_inner
  File "threading.pyo", line 754, in run
  File "AR2.py", line 726, in threadProg
  File "AR2.py", line 472, in executeRow
  File "AR2.py", line 3498, in MoveXYZ
  File "AR2.py", line 4088, in MoveNew
NameError: global name 'ser' is not defined

Exception in Tkinter callback
Traceback (most recent call last):
  File "Tkinter.pyo", line 1536, in __call__
  File "AR2.py", line 665, in stepFwd
  File "AR2.py", line 251, in executeRow
IndexError: tuple index out of range
Exception in Tkinter callback
Traceback (most recent call last):
  File "Tkinter.pyo", line 1536, in __call__
  File "AR2.py", line 687, in stepRev
  File "AR2.py", line 251, in executeRow
IndexError: tuple index out of range
Exception in Tkinter callback
Traceback (most recent call last):
  File "Tkinter.pyo", line 1536, in __call__
  File "AR2.py", line 687, in stepRev
  File "AR2.py", line 251, in executeRow
IndexError: tuple index out of range
Exception in Tkinter callback
Traceback (most recent call last):
  File "Tkinter.pyo", line 1536, in __call__
  File "AR2.py", line 1498, in J1jogPos
NameError: global name 'ser' is not defined
Exception in Tkinter callback
Traceback (most recent call last):
  File "Tkinter.pyo", line 1536, in __call__
  File "AR2.py", line 1498, in J1jogPos
NameError: global name 'ser' is not defined
Exception in Tkinter callback
Traceback (most recent call last):
  File "Tkinter.pyo", line 1536, in __call__
  File "AR2.py", line 1572, in J2jogPos
NameError: global name 'ser' is not defined
Exception in Tkinter callback
Traceback (most recent call last):
  File "Tkinter.pyo", line 1536, in __call__
  File "AR2.py", line 1572, in J2jogPos
NameError: global name 'ser' is not defined
Exception in Tkinter callback
Traceback (most recent call last):
  File "Tkinter.pyo", line 1536, in __call__
  File "AR2.py", line 1646, in J3jogPos
NameError: global name 'ser' is not defined
Exception in Tkinter callback
Traceback (most recent call last):
  File "Tkinter.pyo", line 1536, in __call__
  File "AR2.py", line 1720, in J4jogPos
NameError: global name 'ser' is not defined
Exception in Tkinter callback
Traceback (most recent call last):
  File "Tkinter.pyo", line 1536, in __call__
  File "AR2.py", line 1795, in J5jogPos
NameError: global name 'ser' is not defined
Exception in Tkinter callback
Traceback (most recent call last):
  File "Tkinter.pyo", line 1536, in __call__
  File "AR2.py", line 1869, in J6jogPos
NameError: global name 'ser' is not defined
Exception in thread Thread-2:
Traceback (most recent call last):
  File "threading.pyo", line 801, in __bootstrap_inner
  File "threading.pyo", line 754, in run
  File "AR2.py", line 726, in threadProg
  File "AR2.py", line 472, in executeRow
  File "AR2.py", line 3498, in MoveXYZ
  File "AR2.py", line 4088, in MoveNew
NameError: global name 'ser' is not defined

Exception in Tkinter callback
Traceback (most recent call last):
  File "Tkinter.pyo", line 1536, in __call__
  File "AR2.py", line 225, in setCom
  File "serial\serialwin32.pyo", line 31, in __init__
  File "serial\serialutil.pyo", line 182, in __init__
  File "serial\serialwin32.pyo", line 62, in open
SerialException: could not open port 'COM10': WindowsError(2, 'The system cannot find the file specified.')
Exception in Tkinter callback
Traceback (most recent call last):
  File "Tkinter.pyo", line 1536, in __call__
  File "AR2.py", line 225, in setCom
  File "serial\serialwin32.pyo", line 31, in __init__
  File "serial\serialutil.pyo", line 182, in __init__
  File "serial\serialwin32.pyo", line 62, in open
SerialException: could not open port 'COM5': WindowsError(5, 'Access is denied.')
Exception in Tkinter callback
Traceback (most recent call last):
  File "Tkinter.pyo", line 1536, in __call__
  File "AR2.py", line 225, in setCom
  File "serial\serialwin32.pyo", line 31, in __init__
  File "serial\serialutil.pyo", line 182, in __init__
  File "serial\serialwin32.pyo", line 62, in open
SerialException: could not open port 'COM5': WindowsError(5, 'Access is denied.')
Exception in Tkinter callback
Traceback (most recent call last):
  File "Tkinter.pyo", line 1536, in __call__
  File "AR2.py", line 1498, in J1jogPos
  File "serial\serialwin32.pyo", line 314, in write
SerialException: WriteFile failed (WindowsError(22, 'The device does not recognize the command.'))
Exception in Tkinter callback
Traceback (most recent call last):
  File "Tkinter.pyo", line 1536, in __call__
  File "AR2.py", line 1498, in J1jogPos
  File "serial\serialwin32.pyo", line 314, in write
SerialException: WriteFile failed (WindowsError(22, 'The device does not recognize the command.'))
Exception in Tkinter callback
Traceback (most recent call last):
  File "Tkinter.pyo", line 1536, in __call__
  File "AR2.py", line 1498, in J1jogPos
  File "serial\serialwin32.pyo", line 314, in write
SerialException: WriteFile failed (WindowsError(22, 'The device does not recognize the command.'))
Exception in Tkinter callback
Traceback (most recent call last):
  File "Tkinter.pyo", line 1536, in __call__
  File "AR2.py", line 1572, in J2jogPos
  File "serial\serialwin32.pyo", line 314, in write
SerialException: WriteFile failed (WindowsError(22, 'The device does not recognize the command.'))
Exception in Tkinter callback
Traceback (most recent call last):
  File "Tkinter.pyo", line 1536, in __call__
  File "AR2.py", line 1572, in J2jogPos
  File "serial\serialwin32.pyo", line 314, in write
SerialException: WriteFile failed (WindowsError(22, 'The device does not recognize the command.'))
Exception in Tkinter callback
Traceback (most recent call last):
  File "Tkinter.pyo", line 1536, in __call__
  File "AR2.py", line 1572, in J2jogPos
  File "serial\serialwin32.pyo", line 314, in write
SerialException: WriteFile failed (WindowsError(22, 'The device does not recognize the command.'))
Exception in Tkinter callback
Traceback (most recent call last):
  File "Tkinter.pyo", line 1536, in __call__
  File "AR2.py", line 1646, in J3jogPos
  File "serial\serialwin32.pyo", line 314, in write
SerialException: WriteFile failed (WindowsError(22, 'The device does not recognize the command.'))
Exception in Tkinter callback
Traceback (most recent call last):
  File "Tkinter.pyo", line 1536, in __call__
  File "AR2.py", line 1646, in J3jogPos
  File "serial\serialwin32.pyo", line 314, in write
SerialException: WriteFile failed (WindowsError(22, 'The device does not recognize the command.'))
Exception in Tkinter callback
Traceback (most recent call last):
  File "Tkinter.pyo", line 1536, in __call__
  File "AR2.py", line 1646, in J3jogPos
  File "serial\serialwin32.pyo", line 314, in write
SerialException: WriteFile failed (WindowsError(22, 'The device does not recognize the command.'))
Exception in Tkinter callback
Traceback (most recent call last):
  File "Tkinter.pyo", line 1536, in __call__
  File "AR2.py", line 1720, in J4jogPos
  File "serial\serialwin32.pyo", line 314, in write
SerialException: WriteFile failed (WindowsError(22, 'The device does not recognize the command.'))
Exception in Tkinter callback
Traceback (most recent call last):
  File "Tkinter.pyo", line 1536, in __call__
  File "AR2.py", line 1720, in J4jogPos
  File "serial\serialwin32.pyo", line 314, in write
SerialException: WriteFile failed (WindowsError(22, 'The device does not recognize the command.'))
Exception in Tkinter callback
Traceback (most recent call last):
  File "Tkinter.pyo", line 1536, in __call__
  File "AR2.py", line 1795, in J5jogPos
  File "serial\serialwin32.pyo", line 314, in write
SerialException: WriteFile failed (WindowsError(22, 'The device does not recognize the command.'))
Exception in Tkinter callback
Traceback (most recent call last):
  File "Tkinter.pyo", line 1536, in __call__
  File "AR2.py", line 1795, in J5jogPos
  File "serial\serialwin32.pyo", line 314, in write
SerialException: WriteFile failed (WindowsError(22, 'The device does not recognize the command.'))
Exception in Tkinter callback
Traceback (most recent call last):
  File "Tkinter.pyo", line 1536, in __call__
  File "AR2.py", line 1869, in J6jogPos
  File "serial\serialwin32.pyo", line 314, in write
SerialException: WriteFile failed (WindowsError(22, 'The device does not recognize the command.'))
Exception in Tkinter callback
Traceback (most recent call last):
  File "Tkinter.pyo", line 1536, in __call__
  File "AR2.py", line 1869, in J6jogPos
  File "serial\serialwin32.pyo", line 314, in write
SerialException: WriteFile failed (WindowsError(22, 'The device does not recognize the command.'))
Exception in Tkinter callback
Traceback (most recent call last):
  File "Tkinter.pyo", line 1536, in __call__
  File "AR2.py", line 1498, in J1jogPos
  File "serial\serialwin32.pyo", line 314, in write
SerialException: WriteFile failed (WindowsError(22, 'The device does not recognize the command.'))
Exception in Tkinter callback
Traceback (most recent call last):
  File "Tkinter.pyo", line 1536, in __call__
  File "AR2.py", line 1572, in J2jogPos
  File "serial\serialwin32.pyo", line 314, in write
SerialException: WriteFile failed (WindowsError(22, 'The device does not recognize the command.'))
Exception in Tkinter callback
Traceback (most recent call last):
  File "Tkinter.pyo", line 1536, in __call__
  File "AR2.py", line 1646, in J3jogPos
  File "serial\serialwin32.pyo", line 314, in write
SerialException: WriteFile failed (WindowsError(22, 'The device does not recognize the command.'))
Exception in Tkinter callback
Traceback (most recent call last):
  File "Tkinter.pyo", line 1536, in __call__
  File "AR2.py", line 1720, in J4jogPos
  File "serial\serialwin32.pyo", line 314, in write
SerialException: WriteFile failed (WindowsError(22, 'The device does not recognize the command.'))
Exception in Tkinter callback
Traceback (most recent call last):
  File "Tkinter.pyo", line 1536, in __call__
  File "AR2.py", line 1795, in J5jogPos
  File "serial\serialwin32.pyo", line 314, in write
SerialException: WriteFile failed (WindowsError(22, 'The device does not recognize the command.'))
Exception in Tkinter callback
Traceback (most recent call last):
  File "Tkinter.pyo", line 1536, in __call__
  File "AR2.py", line 1869, in J6jogPos
  File "serial\serialwin32.pyo", line 314, in write
SerialException: WriteFile failed (WindowsError(22, 'The device does not recognize the command.'))
Exception in Tkinter callback
Traceback (most recent call last):
  File "Tkinter.pyo", line 1536, in __call__
  File "AR2.py", line 1498, in J1jogPos
  File "serial\serialwin32.pyo", line 314, in write
SerialException: WriteFile failed (WindowsError(22, 'The device does not recognize the command.'))
Exception in Tkinter callback
Traceback (most recent call last):
  File "Tkinter.pyo", line 1536, in __call__
  File "AR2.py", line 1498, in J1jogPos
  File "serial\serialwin32.pyo", line 314, in write
SerialException: WriteFile failed (WindowsError(22, 'The device does not recognize the command.'))
Exception in Tkinter callback
Traceback (most recent call last):
  File "Tkinter.pyo", line 1536, in __call__
  File "AR2.py", line 1498, in J1jogPos
  File "serial\serialwin32.pyo", line 314, in write
SerialException: WriteFile failed (WindowsError(22, 'The device does not recognize the command.'))
Exception in Tkinter callback
Traceback (most recent call last):
  File "Tkinter.pyo", line 1536, in __call__
  File "AR2.py", line 1498, in J1jogPos
  File "serial\serialwin32.pyo", line 314, in write
SerialException: WriteFile failed (WindowsError(22, 'The device does not recognize the command.'))
Exception in thread Thread-6:
Traceback (most recent call last):
  File "threading.pyo", line 801, in __bootstrap_inner
  File "threading.pyo", line 754, in run
  File "AR2.py", line 726, in threadProg
  File "AR2.py", line 472, in executeRow
  File "AR2.py", line 3498, in MoveXYZ
  File "AR2.py", line 4088, in MoveNew
  File "serial\serialwin32.pyo", line 314, in write
SerialException: WriteFile failed (WindowsError(22, 'The device does not recognize the command.'))

Exception in Tkinter callback
Traceback (most recent call last):
  File "Tkinter.pyo", line 1536, in __call__
  File "AR2.py", line 225, in setCom
  File "serial\serialwin32.pyo", line 31, in __init__
  File "serial\serialutil.pyo", line 182, in __init__
  File "serial\serialwin32.pyo", line 62, in open
SerialException: could not open port 'COM5': WindowsError(5, 'Access is denied.')
Exception in Tkinter callback
Traceback (most recent call last):
  File "Tkinter.pyo", line 1536, in __call__
  File "AR2.py", line 1498, in J1jogPos
NameError: global name 'ser' is not defined
Exception in Tkinter callback
Traceback (most recent call last):
  File "Tkinter.pyo", line 1536, in __call__
  File "AR2.py", line 1498, in J1jogPos
NameError: global name 'ser' is not defined
Exception in Tkinter callback
Traceback (most recent call last):
  File "Tkinter.pyo", line 1536, in __call__
  File "AR2.py", line 225, in setCom
  File "serial\serialwin32.pyo", line 31, in __init__
  File "serial\serialutil.pyo", line 182, in __init__
  File "serial\serialwin32.pyo", line 62, in open
SerialException: could not open port 'COM5': WindowsError(2, 'The system cannot find the file specified.')
Exception in thread Thread-1:
Traceback (most recent call last):
  File "threading.pyo", line 801, in __bootstrap_inner
  File "threading.pyo", line 754, in run
  File "AR2.py", line 726, in threadProg
  File "AR2.py", line 472, in executeRow
  File "AR2.py", line 3498, in MoveXYZ
  File "AR2.py", line 4088, in MoveNew
NameError: global name 'ser' is not defined

Exception in Tkinter callback
Traceback (most recent call last):
  File "Tkinter.pyo", line 1536, in __call__
  File "AR2.py", line 1498, in J1jogPos
NameError: global name 'ser' is not defined
Exception in Tkinter callback
Traceback (most recent call last):
  File "Tkinter.pyo", line 1536, in __call__
  File "AR2.py", line 1498, in J1jogPos
NameError: global name 'ser' is not defined
Exception in Tkinter callback
Traceback (most recent call last):
  File "Tkinter.pyo", line 1536, in __call__
  File "AR2.py", line 768, in calRobotAll
  File "AR2.py", line 957, in calRobot
NameError: global name 'ser' is not defined
Exception in Tkinter callback
Traceback (most recent call last):
  File "Tkinter.pyo", line 1536, in __call__
  File "AR2.py", line 225, in setCom
  File "serial\serialwin32.pyo", line 31, in __init__
  File "serial\serialutil.pyo", line 182, in __init__
  File "serial\serialwin32.pyo", line 62, in open
SerialException: could not open port 'COM5': WindowsError(5, 'Access is denied.')
Exception in Tkinter callback
Traceback (most recent call last):
  File "Tkinter.pyo", line 1536, in __call__
  File "AR2.py", line 1707, in J4jogPos
ValueError: could not convert string to float: 
Exception in Tkinter callback
Traceback (most recent call last):
  File "Tkinter.pyo", line 1536, in __call__
  File "AR2.py", line 1707, in J4jogPos
ValueError: could not convert string to float: 
Exception in Tkinter callback
Traceback (most recent call last):
  File "Tkinter.pyo", line 1536, in __call__
  File "AR2.py", line 1707, in J4jogPos
ValueError: could not convert string to float: 
Exception in Tkinter callback
Traceback (most recent call last):
  File "Tkinter.pyo", line 1536, in __call__
  File "AR2.py", line 1671, in J4jogNeg
ValueError: could not convert string to float: 
Exception in Tkinter callback
Traceback (most recent call last):
  File "Tkinter.pyo", line 1536, in __call__
  File "AR2.py", line 1498, in J1jogPos
  File "serial\serialwin32.pyo", line 314, in write
SerialException: WriteFile failed (WindowsError(22, 'The device does not recognize the command.'))
Exception in Tkinter callback
Traceback (most recent call last):
  File "Tkinter.pyo", line 1536, in __call__
  File "AR2.py", line 1498, in J1jogPos
  File "serial\serialwin32.pyo", line 314, in write
SerialException: WriteFile failed (WindowsError(22, 'The device does not recognize the command.'))
Exception in Tkinter callback
Traceback (most recent call last):
  File "Tkinter.pyo", line 1536, in __call__
  File "AR2.py", line 1803, in J5jogPos
  File "AR2.py", line 1218, in savePosData
IOError: [Errno 13] Permission denied: 'ARbot.cal'
Exception in Tkinter callback
Traceback (most recent call last):
  File "Tkinter.pyo", line 1536, in __call__
  File "AR2.py", line 665, in stepFwd
  File "AR2.py", line 251, in executeRow
IndexError: tuple index out of range
Exception in Tkinter callback
Traceback (most recent call last):
  File "Tkinter.pyo", line 1536, in __call__
  File "AR2.py", line 687, in stepRev
  File "AR2.py", line 251, in executeRow
IndexError: tuple index out of range
Exception in Tkinter callback
Traceback (most recent call last):
  File "Tkinter.pyo", line 1536, in __call__
  File "AR2.py", line 2046, in XjogPos
  File "AR2.py", line 3497, in MoveXYZ
  File "AR2.py", line 3744, in CalcRevKin
ValueError: math domain error
Exception in Tkinter callback
Traceback (most recent call last):
  File "Tkinter.pyo", line 1536, in __call__
  File "AR2.py", line 1911, in XjogNeg
  File "AR2.py", line 3497, in MoveXYZ
  File "AR2.py", line 3744, in CalcRevKin
ValueError: math domain error
Exception in Tkinter callback
Traceback (most recent call last):
  File "Tkinter.pyo", line 1536, in __call__
  File "AR2.py", line 2069, in YjogPos
  File "AR2.py", line 3497, in MoveXYZ
  File "AR2.py", line 3744, in CalcRevKin
ValueError: math domain error
Exception in Tkinter callback
Traceback (most recent call last):
  File "Tkinter.pyo", line 1536, in __call__
  File "AR2.py", line 2069, in YjogPos
  File "AR2.py", line 3497, in MoveXYZ
  File "AR2.py", line 3744, in CalcRevKin
ValueError: math domain error
Exception in Tkinter callback
Traceback (most recent call last):
  File "Tkinter.pyo", line 1536, in __call__
  File "AR2.py", line 2092, in ZjogPos
  File "AR2.py", line 3497, in MoveXYZ
  File "AR2.py", line 3744, in CalcRevKin
ValueError: math domain error
Exception in Tkinter callback
Traceback (most recent call last):
  File "Tkinter.pyo", line 1536, in __call__
  File "AR2.py", line 2001, in RyjogNeg
  File "AR2.py", line 3497, in MoveXYZ
  File "AR2.py", line 3744, in CalcRevKin
ValueError: math domain error
Exception in Tkinter callback
Traceback (most recent call last):
  File "Tkinter.pyo", line 1536, in __call__
  File "AR2.py", line 2137, in RyjogPos
  File "AR2.py", line 3497, in MoveXYZ
  File "AR2.py", line 3744, in CalcRevKin
ValueError: math domain error
Exception in Tkinter callback
Traceback (most recent call last):
  File "Tkinter.pyo", line 1536, in __call__
  File "AR2.py", line 225, in setCom
  File "serial\serialwin32.pyo", line 31, in __init__
  File "serial\serialutil.pyo", line 182, in __init__
  File "serial\serialwin32.pyo", line 62, in open
SerialException: could not open port 'COM5': WindowsError(5, 'Access is denied.')
Exception in Tkinter callback
Traceback (most recent call last):
  File "Tkinter.pyo", line 1536, in __call__
  File "AR2.py", line 225, in setCom
  File "serial\serialwin32.pyo", line 31, in __init__
  File "serial\serialutil.pyo", line 182, in __init__
  File "serial\serialwin32.pyo", line 62, in open
SerialException: could not open port 'COM5': WindowsError(5, 'Access is denied.')
Exception in Tkinter callback
Traceback (most recent call last):
  File "Tkinter.pyo", line 1536, in __call__
  File "AR2.py", line 1498, in J1jogPos
  File "serial\serialwin32.pyo", line 314, in write
SerialException: WriteFile failed (WindowsError(22, 'The device does not recognize the command.'))
Exception in Tkinter callback
Traceback (most recent call last):
  File "Tkinter.pyo", line 1536, in __call__
  File "AR2.py", line 1498, in J1jogPos
  File "serial\serialwin32.pyo", line 314, in write
SerialException: WriteFile failed (WindowsError(22, 'The device does not recognize the command.'))
Exception in Tkinter callback
Traceback (most recent call last):
  File "Tkinter.pyo", line 1536, in __call__
  File "AR2.py", line 1498, in J1jogPos
  File "serial\serialwin32.pyo", line 314, in write
SerialException: WriteFile failed (WindowsError(22, 'The device does not recognize the command.'))
Exception in Tkinter callback
Traceback (most recent call last):
  File "Tkinter.pyo", line 1536, in __call__
  File "AR2.py", line 1498, in J1jogPos
NameError: global name 'ser' is not defined
Exception in Tkinter callback
Traceback (most recent call last):
  File "Tkinter.pyo", line 1536, in __call__
  File "AR2.py", line 1457, in J1jogNeg
NameError: global name 'ser' is not defined
Exception in Tkinter callback
Traceback (most recent call last):
  File "Tkinter.pyo", line 1536, in __call__
  File "AR2.py", line 225, in setCom
  File "serial\serialwin32.pyo", line 31, in __init__
  File "serial\serialutil.pyo", line 182, in __init__
  File "serial\serialwin32.pyo", line 62, in open
SerialException: could not open port 'COM5': WindowsError(5, 'Access is denied.')
Exception in Tkinter callback
Traceback (most recent call last):
  File "Tkinter.pyo", line 1536, in __call__
  File "AR2.py", line 1803, in J5jogPos
  File "AR2.py", line 1218, in savePosData
IOError: [Errno 13] Permission denied: 'ARbot.cal'
Exception in Tkinter callback
Traceback (most recent call last):
  File "Tkinter.pyo", line 1536, in __call__
  File "AR2.py", line 1457, in J1jogNeg
  File "serial\serialwin32.pyo", line 314, in write
SerialException: WriteFile failed (WindowsError(22, 'The device does not recognize the command.'))
Exception in Tkinter callback
Traceback (most recent call last):
  File "Tkinter.pyo", line 1536, in __call__
  File "AR2.py", line 1457, in J1jogNeg
  File "serial\serialwin32.pyo", line 314, in write
SerialException: WriteFile failed (WindowsError(22, 'The device does not recognize the command.'))
Exception in Tkinter callback
Traceback (most recent call last):
  File "Tkinter.pyo", line 1536, in __call__
  File "AR2.py", line 1457, in J1jogNeg
  File "serial\serialwin32.pyo", line 314, in write
SerialException: WriteFile failed (WindowsError(22, 'The device does not recognize the command.'))
Exception in Tkinter callback
Traceback (most recent call last):
  File "Tkinter.pyo", line 1536, in __call__
  File "AR2.py", line 1457, in J1jogNeg
  File "serial\serialwin32.pyo", line 314, in write
SerialException: WriteFile failed (WindowsError(22, 'The device does not recognize the command.'))
Exception in Tkinter callback
Traceback (most recent call last):
  File "Tkinter.pyo", line 1536, in __call__
  File "AR2.py", line 1457, in J1jogNeg
  File "serial\serialwin32.pyo", line 314, in write
SerialException: WriteFile failed (WindowsError(22, 'The device does not recognize the command.'))
Exception in Tkinter callback
Traceback (most recent call last):
  File "Tkinter.pyo", line 1536, in __call__
  File "AR2.py", line 1457, in J1jogNeg
  File "serial\serialwin32.pyo", line 314, in write
SerialException: WriteFile failed (WindowsError(22, 'The device does not recognize the command.'))
Exception in Tkinter callback
Traceback (most recent call last):
  File "Tkinter.pyo", line 1536, in __call__
  File "AR2.py", line 1457, in J1jogNeg
  File "serial\serialwin32.pyo", line 314, in write
SerialException: WriteFile failed (WindowsError(22, 'The device does not recognize the command.'))
Exception in Tkinter callback
Traceback (most recent call last):
  File "Tkinter.pyo", line 1536, in __call__
  File "AR2.py", line 1457, in J1jogNeg
  File "serial\serialwin32.pyo", line 314, in write
SerialException: WriteFile failed (WindowsError(22, 'The device does not recognize the command.'))
Exception in Tkinter callback
Traceback (most recent call last):
  File "Tkinter.pyo", line 1536, in __call__
  File "AR2.py", line 1457, in J1jogNeg
  File "serial\serialwin32.pyo", line 314, in write
SerialException: WriteFile failed (WindowsError(22, 'The device does not recognize the command.'))
Exception in Tkinter callback
Traceback (most recent call last):
  File "Tkinter.pyo", line 1536, in __call__
  File "AR2.py", line 1457, in J1jogNeg
  File "serial\serialwin32.pyo", line 314, in write
SerialException: WriteFile failed (WindowsError(22, 'The device does not recognize the command.'))
Exception in Tkinter callback
Traceback (most recent call last):
  File "Tkinter.pyo", line 1536, in __call__
  File "AR2.py", line 1457, in J1jogNeg
  File "serial\serialwin32.pyo", line 314, in write
SerialException: WriteFile failed (WindowsError(22, 'The device does not recognize the command.'))
Exception in Tkinter callback
Traceback (most recent call last):
  File "Tkinter.pyo", line 1536, in __call__
  File "AR2.py", line 1457, in J1jogNeg
  File "serial\serialwin32.pyo", line 314, in write
SerialException: WriteFile failed (WindowsError(22, 'The device does not recognize the command.'))
Exception in Tkinter callback
Traceback (most recent call last):
  File "Tkinter.pyo", line 1536, in __call__
  File "AR2.py", line 1457, in J1jogNeg
  File "serial\serialwin32.pyo", line 314, in write
SerialException: WriteFile failed (WindowsError(22, 'The device does not recognize the command.'))
Exception in Tkinter callback
Traceback (most recent call last):
  File "Tkinter.pyo", line 1536, in __call__
  File "AR2.py", line 1457, in J1jogNeg
  File "serial\serialwin32.pyo", line 314, in write
SerialException: WriteFile failed (WindowsError(22, 'The device does not recognize the command.'))
Exception in Tkinter callback
Traceback (most recent call last):
  File "Tkinter.pyo", line 1536, in __call__
  File "AR2.py", line 1457, in J1jogNeg
  File "serial\serialwin32.pyo", line 314, in write
SerialException: WriteFile failed (WindowsError(22, 'The device does not recognize the command.'))
Exception in Tkinter callback
Traceback (most recent call last):
  File "Tkinter.pyo", line 1536, in __call__
  File "AR2.py", line 1457, in J1jogNeg
  File "serial\serialwin32.pyo", line 314, in write
SerialException: WriteFile failed (WindowsError(22, 'The device does not recognize the command.'))
Exception in Tkinter callback
Traceback (most recent call last):
  File "Tkinter.pyo", line 1536, in __call__
  File "AR2.py", line 1457, in J1jogNeg
  File "serial\serialwin32.pyo", line 314, in write
SerialException: WriteFile failed (WindowsError(22, 'The device does not recognize the command.'))
Exception in Tkinter callback
Traceback (most recent call last):
  File "Tkinter.pyo", line 1536, in __call__
  File "AR2.py", line 1457, in J1jogNeg
  File "serial\serialwin32.pyo", line 314, in write
SerialException: WriteFile failed (WindowsError(22, 'The device does not recognize the command.'))
Exception in Tkinter callback
Traceback (most recent call last):
  File "Tkinter.pyo", line 1536, in __call__
  File "AR2.py", line 1457, in J1jogNeg
  File "serial\serialwin32.pyo", line 314, in write
SerialException: WriteFile failed (WindowsError(22, 'The device does not recognize the command.'))
Exception in Tkinter callback
Traceback (most recent call last):
  File "Tkinter.pyo", line 1536, in __call__
  File "AR2.py", line 1457, in J1jogNeg
  File "serial\serialwin32.pyo", line 314, in write
SerialException: WriteFile failed (WindowsError(22, 'The device does not recognize the command.'))
Exception in Tkinter callback
Traceback (most recent call last):
  File "Tkinter.pyo", line 1536, in __call__
  File "AR2.py", line 1457, in J1jogNeg
  File "serial\serialwin32.pyo", line 314, in write
SerialException: WriteFile failed (WindowsError(22, 'The device does not recognize the command.'))
Exception in Tkinter callback
Traceback (most recent call last):
  File "Tkinter.pyo", line 1536, in __call__
  File "AR2.py", line 1457, in J1jogNeg
  File "serial\serialwin32.pyo", line 314, in write
SerialException: WriteFile failed (WindowsError(22, 'The device does not recognize the command.'))
Exception in Tkinter callback
Traceback (most recent call last):
  File "Tkinter.pyo", line 1536, in __call__
  File "AR2.py", line 1457, in J1jogNeg
  File "serial\serialwin32.pyo", line 314, in write
SerialException: WriteFile failed (WindowsError(22, 'The device does not recognize the command.'))
Exception in Tkinter callback
Traceback (most recent call last):
  File "Tkinter.pyo", line 1536, in __call__
  File "AR2.py", line 1498, in J1jogPos
  File "serial\serialwin32.pyo", line 314, in write
SerialException: WriteFile failed (WindowsError(22, 'The device does not recognize the command.'))
Exception in Tkinter callback
Traceback (most recent call last):
  File "Tkinter.pyo", line 1536, in __call__
  File "AR2.py", line 1457, in J1jogNeg
  File "serial\serialwin32.pyo", line 314, in write
SerialException: WriteFile failed (WindowsError(22, 'The device does not recognize the command.'))
Exception in Tkinter callback
Traceback (most recent call last):
  File "Tkinter.pyo", line 1536, in __call__
  File "AR2.py", line 1498, in J1jogPos
  File "serial\serialwin32.pyo", line 314, in write
SerialException: WriteFile failed (WindowsError(22, 'The device does not recognize the command.'))
Exception in Tkinter callback
Traceback (most recent call last):
  File "Tkinter.pyo", line 1536, in __call__
  File "AR2.py", line 1498, in J1jogPos
  File "serial\serialwin32.pyo", line 314, in write
SerialException: WriteFile failed (WindowsError(22, 'The device does not recognize the command.'))
Exception in Tkinter callback
Traceback (most recent call last):
  File "Tkinter.pyo", line 1536, in __call__
  File "AR2.py", line 1457, in J1jogNeg
  File "serial\serialwin32.pyo", line 314, in write
SerialException: WriteFile failed (WindowsError(22, 'The device does not recognize the command.'))
Exception in Tkinter callback
Traceback (most recent call last):
  File "Tkinter.pyo", line 1536, in __call__
  File "AR2.py", line 1457, in J1jogNeg
  File "serial\serialwin32.pyo", line 314, in write
SerialException: WriteFile failed (WindowsError(22, 'The device does not recognize the command.'))
Exception in Tkinter callback
Traceback (most recent call last):
  File "Tkinter.pyo", line 1536, in __call__
  File "AR2.py", line 1457, in J1jogNeg
  File "serial\serialwin32.pyo", line 314, in write
SerialException: WriteFile failed (WindowsError(22, 'The device does not recognize the command.'))
Exception in Tkinter callback
Traceback (most recent call last):
  File "Tkinter.pyo", line 1536, in __call__
  File "AR2.py", line 1457, in J1jogNeg
  File "serial\serialwin32.pyo", line 314, in write
SerialException: WriteFile failed (WindowsError(22, 'The device does not recognize the command.'))
Exception in Tkinter callback
Traceback (most recent call last):
  File "Tkinter.pyo", line 1536, in __call__
  File "AR2.py", line 1457, in J1jogNeg
  File "serial\serialwin32.pyo", line 314, in write
SerialException: WriteFile failed (WindowsError(22, 'The device does not recognize the command.'))
Exception in Tkinter callback
Traceback (most recent call last):
  File "Tkinter.pyo", line 1536, in __call__
  File "AR2.py", line 2092, in ZjogPos
  File "AR2.py", line 3497, in MoveXYZ
  File "AR2.py", line 3744, in CalcRevKin
ValueError: math domain error
Exception in Tkinter callback
Traceback (most recent call last):
  File "Tkinter.pyo", line 1536, in __call__
  File "AR2.py", line 2092, in ZjogPos
  File "AR2.py", line 3497, in MoveXYZ
  File "AR2.py", line 3744, in CalcRevKin
ValueError: math domain error
Exception in Tkinter callback
Traceback (most recent call last):
  File "Tkinter.pyo", line 1536, in __call__
  File "AR2.py", line 2092, in ZjogPos
  File "AR2.py", line 3497, in MoveXYZ
  File "AR2.py", line 3744, in CalcRevKin
ValueError: math domain error
Exception in Tkinter callback
Traceback (most recent call last):
  File "Tkinter.pyo", line 1536, in __call__
  File "AR2.py", line 2092, in ZjogPos
  File "AR2.py", line 3497, in MoveXYZ
  File "AR2.py", line 3744, in CalcRevKin
ValueError: math domain error
Exception in Tkinter callback
Traceback (most recent call last):
  File "Tkinter.pyo", line 1536, in __call__
  File "AR2.py", line 2558, in teachInsertBelSelected
UnboundLocalError: local variable 'selRow' referenced before assignment
Exception in Tkinter callback
Traceback (most recent call last):
  File "Tkinter.pyo", line 1536, in __call__
  File "AR2.py", line 2558, in teachInsertBelSelected
UnboundLocalError: local variable 'selRow' referenced before assignment
Exception in Tkinter callback
Traceback (most recent call last):
  File "Tkinter.pyo", line 1536, in __call__
  File "AR2.py", line 2558, in teachInsertBelSelected
UnboundLocalError: local variable 'selRow' referenced before assignment
Exception in Tkinter callback
Traceback (most recent call last):
  File "Tkinter.pyo", line 1536, in __call__
  File "AR2.py", line 2558, in teachInsertBelSelected
UnboundLocalError: local variable 'selRow' referenced before assignment
Exception in Tkinter callback
Traceback (most recent call last):
  File "Tkinter.pyo", line 1536, in __call__
  File "AR2.py", line 2558, in teachInsertBelSelected
UnboundLocalError: local variable 'selRow' referenced before assignment
Exception in Tkinter callback
Traceback (most recent call last):
  File "Tkinter.pyo", line 1536, in __call__
  File "AR2.py", line 2832, in insertCallProg
IndexError: tuple index out of range
Exception in Tkinter callback
Traceback (most recent call last):
  File "Tkinter.pyo", line 1536, in __call__
  File "AR2.py", line 687, in stepRev
  File "AR2.py", line 251, in executeRow
IndexError: tuple index out of range
Exception in Tkinter callback
Traceback (most recent call last):
  File "Tkinter.pyo", line 1536, in __call__
  File "AR2.py", line 665, in stepFwd
  File "AR2.py", line 251, in executeRow
IndexError: tuple index out of range
Exception in Tkinter callback
Traceback (most recent call last):
  File "Tkinter.pyo", line 1536, in __call__
  File "AR2.py", line 687, in stepRev
  File "AR2.py", line 251, in executeRow
IndexError: tuple index out of range
Exception in Tkinter callback
Traceback (most recent call last):
  File "Tkinter.pyo", line 1536, in __call__
  File "AR2.py", line 2558, in teachInsertBelSelected
UnboundLocalError: local variable 'selRow' referenced before assignment
Exception in Tkinter callback
Traceback (most recent call last):
  File "Tkinter.pyo", line 1536, in __call__
  File "AR2.py", line 2677, in waitTime
IndexError: tuple index out of range
Exception in Tkinter callback
Traceback (most recent call last):
  File "Tkinter.pyo", line 1536, in __call__
  File "AR2.py", line 2558, in teachInsertBelSelected
UnboundLocalError: local variable 'selRow' referenced before assignment
Exception in Tkinter callback
Traceback (most recent call last):
  File "Tkinter.pyo", line 1536, in __call__
  File "AR2.py", line 687, in stepRev
  File "AR2.py", line 251, in executeRow
IndexError: tuple index out of range
Exception in Tkinter callback
Traceback (most recent call last):
  File "Tkinter.pyo", line 1536, in __call__
  File "AR2.py", line 687, in stepRev
  File "AR2.py", line 251, in executeRow
IndexError: tuple index out of range
Exception in Tkinter callback
Traceback (most recent call last):
  File "Tkinter.pyo", line 1536, in __call__
  File "AR2.py", line 2677, in waitTime
IndexError: tuple index out of range
Exception in Tkinter callback
Traceback (most recent call last):
  File "Tkinter.pyo", line 1536, in __call__
  File "AR2.py", line 2558, in teachInsertBelSelected
UnboundLocalError: local variable 'selRow' referenced before assignment
Exception in Tkinter callback
Traceback (most recent call last):
  File "Tkinter.pyo", line 1536, in __call__
  File "AR2.py", line 2558, in teachInsertBelSelected
UnboundLocalError: local variable 'selRow' referenced before assignment
Exception in Tkinter callback
Traceback (most recent call last):
  File "Tkinter.pyo", line 1536, in __call__
  File "AR2.py", line 2677, in waitTime
IndexError: tuple index out of range
Exception in Tkinter callback
Traceback (most recent call last):
  File "Tkinter.pyo", line 1536, in __call__
  File "AR2.py", line 2558, in teachInsertBelSelected
UnboundLocalError: local variable 'selRow' referenced before assignment
Exception in Tkinter callback
Traceback (most recent call last):
  File "Tkinter.pyo", line 1536, in __call__
  File "AR2.py", line 2558, in teachInsertBelSelected
UnboundLocalError: local variable 'selRow' referenced before assignment
Exception in Tkinter callback
Traceback (most recent call last):
  File "Tkinter.pyo", line 1536, in __call__
  File "AR2.py", line 2558, in teachInsertBelSelected
UnboundLocalError: local variable 'selRow' referenced before assignment
Exception in Tkinter callback
Traceback (most recent call last):
  File "Tkinter.pyo", line 1536, in __call__
  File "AR2.py", line 2558, in teachInsertBelSelected
UnboundLocalError: local variable 'selRow' referenced before assignment
Exception in thread Thread-1:
Traceback (most recent call last):
  File "threading.pyo", line 801, in __bootstrap_inner
  File "threading.pyo", line 754, in run
  File "AR2.py", line 726, in threadProg
  File "AR2.py", line 271, in executeRow
AttributeError: Frame instance has no attribute 'lastRow'

Exception in thread Thread-2:
Traceback (most recent call last):
  File "threading.pyo", line 801, in __bootstrap_inner
  File "threading.pyo", line 754, in run
  File "AR2.py", line 726, in threadProg
  File "AR2.py", line 271, in executeRow
AttributeError: Frame instance has no attribute 'lastRow'

Exception in Tkinter callback
Traceback (most recent call last):
  File "Tkinter.pyo", line 1536, in __call__
  File "AR2.py", line 1613, in J3jogNeg
  File "AR2.py", line 1218, in savePosData
IOError: [Errno 13] Permission denied: 'ARbot.cal'
Exception in Tkinter callback
Traceback (most recent call last):
  File "Tkinter.pyo", line 1536, in __call__
  File "AR2.py", line 2558, in teachInsertBelSelected
UnboundLocalError: local variable 'selRow' referenced before assignment
Exception in Tkinter callback
Traceback (most recent call last):
  File "Tkinter.pyo", line 1536, in __call__
  File "AR2.py", line 2558, in teachInsertBelSelected
UnboundLocalError: local variable 'selRow' referenced before assignment
Exception in Tkinter callback
Traceback (most recent call last):
  File "Tkinter.pyo", line 1536, in __call__
  File "AR2.py", line 2069, in YjogPos
  File "AR2.py", line 3498, in MoveXYZ
  File "AR2.py", line 4108, in MoveNew
  File "AR2.py", line 1218, in savePosData
IOError: [Errno 13] Permission denied: 'ARbot.cal'
Exception in thread Thread-6:
Traceback (most recent call last):
  File "threading.pyo", line 801, in __bootstrap_inner
  File "threading.pyo", line 754, in run
  File "AR2.py", line 726, in threadProg
  File "AR2.py", line 271, in executeRow
AttributeError: Frame instance has no attribute 'lastRow'

Exception in thread Thread-1:
Traceback (most recent call last):
  File "threading.pyo", line 801, in __bootstrap_inner
  File "threading.pyo", line 754, in run
  File "AR2.py", line 726, in threadProg
  File "AR2.py", line 271, in executeRow
AttributeError: Frame instance has no attribute 'lastRow'

Exception in thread Thread-3:
Traceback (most recent call last):
  File "threading.pyo", line 801, in __bootstrap_inner
  File "threading.pyo", line 754, in run
  File "AR2.py", line 726, in threadProg
  File "AR2.py", line 271, in executeRow
AttributeError: Frame instance has no attribute 'lastRow'

Exception in Tkinter callback
Traceback (most recent call last):
  File "Tkinter.pyo", line 1536, in __call__
  File "AR2.py", line 2558, in teachInsertBelSelected
UnboundLocalError: local variable 'selRow' referenced before assignment
Exception in Tkinter callback
Traceback (most recent call last):
  File "Tkinter.pyo", line 1536, in __call__
  File "AR2.py", line 1803, in J5jogPos
  File "AR2.py", line 1218, in savePosData
IOError: [Errno 13] Permission denied: 'ARbot.cal'
Exception in Tkinter callback
Traceback (most recent call last):
  File "Tkinter.pyo", line 1536, in __call__
  File "AR2.py", line 2558, in teachInsertBelSelected
UnboundLocalError: local variable 'selRow' referenced before assignment
Exception in Tkinter callback
Traceback (most recent call last):
  File "Tkinter.pyo", line 1536, in __call__
  File "AR2.py", line 2558, in teachInsertBelSelected
UnboundLocalError: local variable 'selRow' referenced before assignment
Exception in thread Thread-11:
Traceback (most recent call last):
  File "threading.pyo", line 801, in __bootstrap_inner
  File "threading.pyo", line 754, in run
  File "AR2.py", line 729, in threadProg
IndexError: tuple index out of range

Exception in thread Thread-19:
Traceback (most recent call last):
  File "threading.pyo", line 801, in __bootstrap_inner
  File "threading.pyo", line 754, in run
  File "AR2.py", line 718, in threadProg
  File "Tkinter.pyo", line 2664, in selection_set
TclError: ambiguous option "": must be anchor, clear, includes, or set

Exception in thread Thread-2:
Traceback (most recent call last):
  File "threading.pyo", line 801, in __bootstrap_inner
  File "threading.pyo", line 754, in run
  File "AR2.py", line 726, in threadProg
  File "AR2.py", line 271, in executeRow
AttributeError: Frame instance has no attribute 'lastRow'

Exception in Tkinter callback
Traceback (most recent call last):
  File "Tkinter.pyo", line 1536, in __call__
  File "AR2.py", line 688, in stepRev
IndexError: tuple index out of range
Exception in thread Thread-7:
Traceback (most recent call last):
  File "threading.pyo", line 801, in __bootstrap_inner
  File "threading.pyo", line 754, in run
  File "AR2.py", line 726, in threadProg
  File "AR2.py", line 271, in executeRow
AttributeError: Frame instance has no attribute 'lastRow'

Exception in thread Thread-8:
Traceback (most recent call last):
  File "threading.pyo", line 801, in __bootstrap_inner
  File "threading.pyo", line 754, in run
  File "AR2.py", line 726, in threadProg
  File "AR2.py", line 271, in executeRow
AttributeError: Frame instance has no attribute 'lastRow'

Exception in thread Thread-10:
Traceback (most recent call last):
  File "threading.pyo", line 801, in __bootstrap_inner
  File "threading.pyo", line 754, in run
  File "AR2.py", line 726, in threadProg
  File "AR2.py", line 271, in executeRow
AttributeError: Frame instance has no attribute 'lastRow'

Exception in Tkinter callback
Traceback (most recent call last):
  File "Tkinter.pyo", line 1536, in __call__
  File "AR2.py", line 1687, in J4jogNeg
  File "AR2.py", line 1218, in savePosData
IOError: [Errno 13] Permission denied: 'ARbot.cal'
Exception in thread Thread-3:
Traceback (most recent call last):
  File "threading.pyo", line 801, in __bootstrap_inner
  File "threading.pyo", line 754, in run
  File "AR2.py", line 729, in threadProg
IndexError: tuple index out of range

Exception in thread Thread-4:
Traceback (most recent call last):
  File "threading.pyo", line 801, in __bootstrap_inner
  File "threading.pyo", line 754, in run
  File "AR2.py", line 726, in threadProg
  File "AR2.py", line 271, in executeRow
AttributeError: Frame instance has no attribute 'lastRow'

Exception in Tkinter callback
Traceback (most recent call last):
  File "Tkinter.pyo", line 1536, in __call__
  File "AR2.py", line 2092, in ZjogPos
  File "AR2.py", line 3497, in MoveXYZ
  File "AR2.py", line 3744, in CalcRevKin
ValueError: math domain error
Exception in thread Thread-5:
Traceback (most recent call last):
  File "threading.pyo", line 801, in __bootstrap_inner
  File "threading.pyo", line 754, in run
  File "AR2.py", line 726, in threadProg
  File "AR2.py", line 271, in executeRow
AttributeError: Frame instance has no attribute 'lastRow'

Exception in Tkinter callback
Traceback (most recent call last):
  File "Tkinter.pyo", line 1536, in __call__
  File "AR2.py", line 2092, in ZjogPos
  File "AR2.py", line 3498, in MoveXYZ
  File "AR2.py", line 4108, in MoveNew
  File "AR2.py", line 1218, in savePosData
IOError: [Errno 13] Permission denied: 'ARbot.cal'
Exception in Tkinter callback
Traceback (most recent call last):
  File "Tkinter.pyo", line 1536, in __call__
  File "AR2.py", line 2558, in teachInsertBelSelected
UnboundLocalError: local variable 'selRow' referenced before assignment
Exception in Tkinter callback
Traceback (most recent call last):
  File "Tkinter.pyo", line 1536, in __call__
  File "AR2.py", line 2558, in teachInsertBelSelected
UnboundLocalError: local variable 'selRow' referenced before assignment
Exception in Tkinter callback
Traceback (most recent call last):
  File "Tkinter.pyo", line 1536, in __call__
  File "AR2.py", line 2558, in teachInsertBelSelected
UnboundLocalError: local variable 'selRow' referenced before assignment
Exception in Tkinter callback
Traceback (most recent call last):
  File "Tkinter.pyo", line 1536, in __call__
  File "AR2.py", line 2558, in teachInsertBelSelected
UnboundLocalError: local variable 'selRow' referenced before assignment
Exception in Tkinter callback
Traceback (most recent call last):
  File "Tkinter.pyo", line 1536, in __call__
  File "AR2.py", line 687, in stepRev
  File "AR2.py", line 251, in executeRow
IndexError: tuple index out of range
Exception in Tkinter callback
Traceback (most recent call last):
  File "Tkinter.pyo", line 1536, in __call__
  File "AR2.py", line 687, in stepRev
  File "AR2.py", line 251, in executeRow
IndexError: tuple index out of range
Exception in Tkinter callback
Traceback (most recent call last):
  File "Tkinter.pyo", line 1536, in __call__
  File "AR2.py", line 2558, in teachInsertBelSelected
UnboundLocalError: local variable 'selRow' referenced before assignment
Exception in Tkinter callback
Traceback (most recent call last):
  File "Tkinter.pyo", line 1536, in __call__
  File "AR2.py", line 2558, in teachInsertBelSelected
UnboundLocalError: local variable 'selRow' referenced before assignment
Exception in Tkinter callback
Traceback (most recent call last):
  File "Tkinter.pyo", line 1536, in __call__
  File "AR2.py", line 2558, in teachInsertBelSelected
UnboundLocalError: local variable 'selRow' referenced before assignment
Exception in Tkinter callback
Traceback (most recent call last):
  File "Tkinter.pyo", line 1536, in __call__
  File "AR2.py", line 2689, in waitInputOn
IndexError: tuple index out of range
Exception in Tkinter callback
Traceback (most recent call last):
  File "Tkinter.pyo", line 1536, in __call__
  File "AR2.py", line 2092, in ZjogPos
  File "AR2.py", line 3497, in MoveXYZ
  File "AR2.py", line 3744, in CalcRevKin
ValueError: math domain error
Exception in Tkinter callback
Traceback (most recent call last):
  File "Tkinter.pyo", line 1536, in __call__
  File "AR2.py", line 1836, in J6jogNeg
  File "AR2.py", line 1218, in savePosData
IOError: [Errno 13] Permission denied: 'ARbot.cal'
Exception in thread Thread-51:
Traceback (most recent call last):
  File "threading.pyo", line 801, in __bootstrap_inner
  File "threading.pyo", line 754, in run
  File "AR2.py", line 726, in threadProg
  File "AR2.py", line 271, in executeRow
AttributeError: Frame instance has no attribute 'lastRow'

Exception in Tkinter callback
Traceback (most recent call last):
  File "Tkinter.pyo", line 1536, in __call__
  File "AR2.py", line 1803, in J5jogPos
  File "AR2.py", line 1218, in savePosData
IOError: [Errno 13] Permission denied: 'ARbot.cal'
Exception in Tkinter callback
Traceback (most recent call last):
  File "Tkinter.pyo", line 1536, in __call__
  File "AR2.py", line 2558, in teachInsertBelSelected
UnboundLocalError: local variable 'selRow' referenced before assignment
Exception in thread Thread-69:
Traceback (most recent call last):
  File "threading.pyo", line 801, in __bootstrap_inner
  File "threading.pyo", line 754, in run
  File "AR2.py", line 718, in threadProg
  File "Tkinter.pyo", line 2664, in selection_set
TclError: invalid command name "1"

Exception in thread Thread-70:
Traceback (most recent call last):
  File "threading.pyo", line 801, in __bootstrap_inner
  File "threading.pyo", line 754, in run
  File "AR2.py", line 726, in threadProg
  File "AR2.py", line 271, in executeRow
AttributeError: Frame instance has no attribute 'lastRow'

Exception in thread Thread-1:
Traceback (most recent call last):
  File "threading.pyo", line 801, in __bootstrap_inner
  File "threading.pyo", line 754, in run
  File "AR2.py", line 726, in threadProg
  File "AR2.py", line 271, in executeRow
AttributeError: Frame instance has no attribute 'lastRow'

Exception in thread Thread-3:
Traceback (most recent call last):
  File "threading.pyo", line 801, in __bootstrap_inner
  File "threading.pyo", line 754, in run
  File "AR2.py", line 726, in threadProg
  File "AR2.py", line 271, in executeRow
AttributeError: Frame instance has no attribute 'lastRow'

Exception in thread Thread-5:
Traceback (most recent call last):
  File "threading.pyo", line 801, in __bootstrap_inner
  File "threading.pyo", line 754, in run
  File "AR2.py", line 726, in threadProg
  File "AR2.py", line 472, in executeRow
  File "AR2.py", line 3498, in MoveXYZ
  File "AR2.py", line 4108, in MoveNew
  File "AR2.py", line 1218, in savePosData
IOError: [Errno 13] Permission denied: 'ARbot.cal'

Exception in thread Thread-6:
Traceback (most recent call last):
  File "threading.pyo", line 801, in __bootstrap_inner
  File "threading.pyo", line 754, in run
  File "AR2.py", line 726, in threadProg
  File "AR2.py", line 271, in executeRow
AttributeError: Frame instance has no attribute 'lastRow'

Exception in Tkinter callback
Traceback (most recent call last):
  File "Tkinter.pyo", line 1536, in __call__
  File "AR2.py", line 1762, in J5jogNeg
  File "AR2.py", line 1218, in savePosData
IOError: [Errno 13] Permission denied: 'ARbot.cal'
Exception in Tkinter callback
Traceback (most recent call last):
  File "Tkinter.pyo", line 1536, in __call__
  File "AR2.py", line 2558, in teachInsertBelSelected
UnboundLocalError: local variable 'selRow' referenced before assignment
Exception in thread Thread-17:
Traceback (most recent call last):
  File "threading.pyo", line 801, in __bootstrap_inner
  File "threading.pyo", line 754, in run
  File "AR2.py", line 726, in threadProg
  File "AR2.py", line 472, in executeRow
  File "AR2.py", line 3498, in MoveXYZ
  File "AR2.py", line 4107, in MoveNew
  File "AR2.py", line 1433, in DisplaySteps
  File "Tkinter.pyo", line 1333, in __setitem__
  File "Tkinter.pyo", line 1326, in configure
  File "Tkinter.pyo", line 1317, in _configure
TclError: invalid command name "-text"

Exception in thread Thread-3:
Traceback (most recent call last):
  File "threading.pyo", line 801, in __bootstrap_inner
  File "threading.pyo", line 754, in run
  File "AR2.py", line 726, in threadProg
  File "AR2.py", line 271, in executeRow
AttributeError: Frame instance has no attribute 'lastRow'

Exception in thread Thread-7:
Traceback (most recent call last):
  File "threading.pyo", line 801, in __bootstrap_inner
  File "threading.pyo", line 754, in run
  File "AR2.py", line 726, in threadProg
  File "AR2.py", line 271, in executeRow
AttributeError: Frame instance has no attribute 'lastRow'

Exception in thread Thread-8:
Traceback (most recent call last):
  File "threading.pyo", line 801, in __bootstrap_inner
  File "threading.pyo", line 754, in run
  File "AR2.py", line 726, in threadProg
  File "AR2.py", line 271, in executeRow
AttributeError: Frame instance has no attribute 'lastRow'

Exception in thread Thread-9:
Traceback (most recent call last):
  File "threading.pyo", line 801, in __bootstrap_inner
  File "threading.pyo", line 754, in run
  File "AR2.py", line 726, in threadProg
  File "AR2.py", line 271, in executeRow
AttributeError: Frame instance has no attribute 'lastRow'

Exception in thread Thread-10:
Traceback (most recent call last):
  File "threading.pyo", line 801, in __bootstrap_inner
  File "threading.pyo", line 754, in run
  File "AR2.py", line 726, in threadProg
  File "AR2.py", line 271, in executeRow
AttributeError: Frame instance has no attribute 'lastRow'

Exception in thread Thread-11:
Traceback (most recent call last):
  File "threading.pyo", line 801, in __bootstrap_inner
  File "threading.pyo", line 754, in run
  File "AR2.py", line 726, in threadProg
  File "AR2.py", line 271, in executeRow
AttributeError: Frame instance has no attribute 'lastRow'

Exception in thread Thread-12:
Traceback (most recent call last):
  File "threading.pyo", line 801, in __bootstrap_inner
  File "threading.pyo", line 754, in run
  File "AR2.py", line 726, in threadProg
  File "AR2.py", line 271, in executeRow
AttributeError: Frame instance has no attribute 'lastRow'

Exception in thread Thread-13:
Traceback (most recent call last):
  File "threading.pyo", line 801, in __bootstrap_inner
  File "threading.pyo", line 754, in run
  File "AR2.py", line 726, in threadProg
  File "AR2.py", line 271, in executeRow
AttributeError: Frame instance has no attribute 'lastRow'

Exception in thread Thread-14:
Traceback (most recent call last):
  File "threading.pyo", line 801, in __bootstrap_inner
  File "threading.pyo", line 754, in run
  File "AR2.py", line 726, in threadProg
  File "AR2.py", line 271, in executeRow
AttributeError: Frame instance has no attribute 'lastRow'

Exception in Tkinter callback
Traceback (most recent call last):
  File "Tkinter.pyo", line 1536, in __call__
  File "AR2.py", line 687, in stepRev
  File "AR2.py", line 251, in executeRow
IndexError: tuple index out of range
Exception in Tkinter callback
Traceback (most recent call last):
  File "Tkinter.pyo", line 1536, in __call__
  File "AR2.py", line 1836, in J6jogNeg
  File "AR2.py", line 1218, in savePosData
IOError: [Errno 13] Permission denied: 'ARbot.cal'
Exception in Tkinter callback
Traceback (most recent call last):
  File "Tkinter.pyo", line 1536, in __call__
  File "AR2.py", line 665, in stepFwd
  File "AR2.py", line 251, in executeRow
IndexError: tuple index out of range
Exception in Tkinter callback
Traceback (most recent call last):
  File "Tkinter.pyo", line 1536, in __call__
  File "AR2.py", line 687, in stepRev
  File "AR2.py", line 251, in executeRow
IndexError: tuple index out of range
Exception in Tkinter callback
Traceback (most recent call last):
  File "Tkinter.pyo", line 1536, in __call__
  File "AR2.py", line 2745, in jumpTab
IndexError: tuple index out of range
Exception in Tkinter callback
Traceback (most recent call last):
  File "Tkinter.pyo", line 1536, in __call__
  File "AR2.py", line 1762, in J5jogNeg
  File "AR2.py", line 1218, in savePosData
IOError: [Errno 13] Permission denied: 'ARbot.cal'
Exception in Tkinter callback
Traceback (most recent call last):
  File "Tkinter.pyo", line 1536, in __call__
  File "AR2.py", line 2558, in teachInsertBelSelected
UnboundLocalError: local variable 'selRow' referenced before assignment
Exception in thread Thread-39:
Traceback (most recent call last):
  File "threading.pyo", line 801, in __bootstrap_inner
  File "threading.pyo", line 754, in run
  File "AR2.py", line 729, in threadProg
IndexError: tuple index out of range

Exception in thread Thread-1:
Traceback (most recent call last):
  File "threading.pyo", line 801, in __bootstrap_inner
  File "threading.pyo", line 754, in run
  File "AR2.py", line 729, in threadProg
IndexError: tuple index out of range

Exception in Tkinter callback
Traceback (most recent call last):
  File "Tkinter.pyo", line 1536, in __call__
  File "AR2.py", line 1457, in J1jogNeg
NameError: global name 'ser' is not defined
Exception in Tkinter callback
Traceback (most recent call last):
  File "Tkinter.pyo", line 1536, in __call__
  File "AR2.py", line 1498, in J1jogPos
NameError: global name 'ser' is not defined
Exception in Tkinter callback
Traceback (most recent call last):
  File "Tkinter.pyo", line 1536, in __call__
  File "AR2.py", line 1457, in J1jogNeg
NameError: global name 'ser' is not defined
Exception in Tkinter callback
Traceback (most recent call last):
  File "Tkinter.pyo", line 1536, in __call__
  File "AR2.py", line 1457, in J1jogNeg
NameError: global name 'ser' is not defined
Exception in Tkinter callback
Traceback (most recent call last):
  File "Tkinter.pyo", line 1536, in __call__
  File "AR2.py", line 1457, in J1jogNeg
NameError: global name 'ser' is not defined
Exception in Tkinter callback
Traceback (most recent call last):
  File "Tkinter.pyo", line 1536, in __call__
  File "AR2.py", line 1498, in J1jogPos
NameError: global name 'ser' is not defined
Exception in Tkinter callback
Traceback (most recent call last):
  File "Tkinter.pyo", line 1536, in __call__
  File "AR2.py", line 1457, in J1jogNeg
NameError: global name 'ser' is not defined
Exception in thread Thread-1:
Traceback (most recent call last):
  File "threading.pyo", line 801, in __bootstrap_inner
  File "threading.pyo", line 754, in run
  File "AR2.py", line 729, in threadProg
IndexError: tuple index out of range

Exception in Tkinter callback
Traceback (most recent call last):
  File "Tkinter.pyo", line 1536, in __call__
  File "AR2.py", line 2558, in teachInsertBelSelected
UnboundLocalError: local variable 'selRow' referenced before assignment
Exception in thread Thread-5:
Traceback (most recent call last):
  File "threading.pyo", line 801, in __bootstrap_inner
  File "threading.pyo", line 754, in run
  File "AR2.py", line 729, in threadProg
IndexError: tuple index out of range

Exception in thread Thread-6:
Traceback (most recent call last):
  File "threading.pyo", line 801, in __bootstrap_inner
  File "threading.pyo", line 754, in run
  File "AR2.py", line 729, in threadProg
IndexError: tuple index out of range

Exception in Tkinter callback
Traceback (most recent call last):
  File "Tkinter.pyo", line 1536, in __call__
  File "AR2.py", line 2558, in teachInsertBelSelected
UnboundLocalError: local variable 'selRow' referenced before assignment
Exception in Tkinter callback
Traceback (most recent call last):
  File "Tkinter.pyo", line 1536, in __call__
  File "AR2.py", line 2663, in manReplItem
IndexError: tuple index out of range
Exception in thread Thread-15:
Traceback (most recent call last):
  File "threading.pyo", line 801, in __bootstrap_inner
  File "threading.pyo", line 754, in run
  File "AR2.py", line 726, in threadProg
  File "AR2.py", line 472, in executeRow
  File "AR2.py", line 3497, in MoveXYZ
  File "AR2.py", line 3744, in CalcRevKin
ValueError: math domain error

Exception in thread Thread-16:
Traceback (most recent call last):
  File "threading.pyo", line 801, in __bootstrap_inner
  File "threading.pyo", line 754, in run
  File "AR2.py", line 726, in threadProg
  File "AR2.py", line 472, in executeRow
  File "AR2.py", line 3497, in MoveXYZ
  File "AR2.py", line 3744, in CalcRevKin
ValueError: math domain error

Exception in thread Thread-23:
Traceback (most recent call last):
  File "threading.pyo", line 801, in __bootstrap_inner
  File "threading.pyo", line 754, in run
  File "AR2.py", line 726, in threadProg
  File "AR2.py", line 271, in executeRow
AttributeError: Frame instance has no attribute 'lastRow'

Exception in thread Thread-24:
Traceback (most recent call last):
  File "threading.pyo", line 801, in __bootstrap_inner
  File "threading.pyo", line 754, in run
  File "AR2.py", line 726, in threadProg
  File "AR2.py", line 271, in executeRow
AttributeError: Frame instance has no attribute 'lastRow'

Exception in thread Thread-25:
Traceback (most recent call last):
  File "threading.pyo", line 801, in __bootstrap_inner
  File "threading.pyo", line 754, in run
  File "AR2.py", line 726, in threadProg
  File "AR2.py", line 271, in executeRow
AttributeError: Frame instance has no attribute 'lastRow'

Exception in thread Thread-26:
Traceback (most recent call last):
  File "threading.pyo", line 801, in __bootstrap_inner
  File "threading.pyo", line 754, in run
  File "AR2.py", line 726, in threadProg
  File "AR2.py", line 271, in executeRow
AttributeError: Frame instance has no attribute 'lastRow'

Exception in Tkinter callback
Traceback (most recent call last):
  File "Tkinter.pyo", line 1536, in __call__
  File "AR2.py", line 2558, in teachInsertBelSelected
UnboundLocalError: local variable 'selRow' referenced before assignment
Exception in Tkinter callback
Traceback (most recent call last):
  File "Tkinter.pyo", line 1536, in __call__
  File "AR2.py", line 2558, in teachInsertBelSelected
UnboundLocalError: local variable 'selRow' referenced before assignment
Exception in thread Thread-35:
Traceback (most recent call last):
  File "threading.pyo", line 801, in __bootstrap_inner
  File "threading.pyo", line 754, in run
  File "AR2.py", line 726, in threadProg
  File "AR2.py", line 271, in executeRow
AttributeError: Frame instance has no attribute 'lastRow'

Exception in thread Thread-36:
Traceback (most recent call last):
  File "threading.pyo", line 801, in __bootstrap_inner
  File "threading.pyo", line 754, in run
  File "AR2.py", line 726, in threadProg
  File "AR2.py", line 271, in executeRow
AttributeError: Frame instance has no attribute 'lastRow'

Exception in thread Thread-1:
Traceback (most recent call last):
  File "threading.pyo", line 801, in __bootstrap_inner
  File "threading.pyo", line 754, in run
  File "AR2.py", line 729, in threadProg
IndexError: tuple index out of range

Exception in thread Thread-2:
Traceback (most recent call last):
  File "threading.pyo", line 801, in __bootstrap_inner
  File "threading.pyo", line 754, in run
  File "AR2.py", line 729, in threadProg
IndexError: tuple index out of range

Exception in thread Thread-6:
Traceback (most recent call last):
  File "threading.pyo", line 801, in __bootstrap_inner
  File "threading.pyo", line 754, in run
  File "AR2.py", line 729, in threadProg
IndexError: tuple index out of range

Exception in thread Thread-8:
Traceback (most recent call last):
  File "threading.pyo", line 801, in __bootstrap_inner
  File "threading.pyo", line 754, in run
  File "AR2.py", line 729, in threadProg
IndexError: tuple index out of range

Exception in Tkinter callback
Traceback (most recent call last):
  File "Tkinter.pyo", line 1536, in __call__
  File "AR2.py", line 2745, in jumpTab
IndexError: tuple index out of range
Exception in thread Thread-17:
Traceback (most recent call last):
  File "threading.pyo", line 801, in __bootstrap_inner
  File "threading.pyo", line 754, in run
  File "AR2.py", line 729, in threadProg
IndexError: tuple index out of range

Exception in thread Thread-18:
Traceback (most recent call last):
  File "threading.pyo", line 801, in __bootstrap_inner
  File "threading.pyo", line 754, in run
  File "AR2.py", line 718, in threadProg
  File "Tkinter.pyo", line 2664, in selection_set
TclError: ambiguous option "": must be anchor, clear, includes, or set

Exception in thread Thread-39:
Traceback (most recent call last):
  File "threading.pyo", line 801, in __bootstrap_inner
  File "threading.pyo", line 754, in run
  File "AR2.py", line 729, in threadProg
IndexError: tuple index out of range

Exception in thread Thread-3:
Traceback (most recent call last):
  File "threading.pyo", line 801, in __bootstrap_inner
  File "threading.pyo", line 754, in run
  File "AR2.py", line 729, in threadProg
IndexError: tuple index out of range

Exception in thread Thread-6:
Traceback (most recent call last):
  File "threading.pyo", line 801, in __bootstrap_inner
  File "threading.pyo", line 754, in run
  File "AR2.py", line 726, in threadProg
  File "AR2.py", line 472, in executeRow
  File "AR2.py", line 3498, in MoveXYZ
  File "AR2.py", line 4108, in MoveNew
  File "AR2.py", line 1218, in savePosData
IOError: [Errno 13] Permission denied: 'ARbot.cal'

Exception in Tkinter callback
Traceback (most recent call last):
  File "Tkinter.pyo", line 1536, in __call__
  File "AR2.py", line 1803, in J5jogPos
  File "AR2.py", line 1218, in savePosData
IOError: [Errno 13] Permission denied: 'ARbot.cal'
Exception in thread Thread-11:
Traceback (most recent call last):
  File "threading.pyo", line 801, in __bootstrap_inner
  File "threading.pyo", line 754, in run
  File "AR2.py", line 729, in threadProg
IndexError: tuple index out of range

Exception in thread Thread-13:
Traceback (most recent call last):
  File "threading.pyo", line 801, in __bootstrap_inner
  File "threading.pyo", line 754, in run
  File "AR2.py", line 729, in threadProg
IndexError: tuple index out of range

Exception in thread Thread-16:
Traceback (most recent call last):
  File "threading.pyo", line 801, in __bootstrap_inner
  File "threading.pyo", line 754, in run
  File "AR2.py", line 732, in threadProg
  File "Tkinter.pyo", line 2681, in itemconfigure
  File "Tkinter.pyo", line 1317, in _configure
TclError: bad option "-fg": must be activate, bbox, cget, configure, curselection, delete, get, index, insert, itemcget, itemconfigure, nearest, scan, see, selection, size, xview, or yview

Exception in thread Thread-1:
Traceback (most recent call last):
  File "threading.pyo", line 801, in __bootstrap_inner
  File "threading.pyo", line 754, in run
  File "AR2.py", line 726, in threadProg
  File "AR2.py", line 472, in executeRow
  File "AR2.py", line 3498, in MoveXYZ
  File "AR2.py", line 4088, in MoveNew
  File "serial\serialwin32.pyo", line 314, in write
SerialException: WriteFile failed (WindowsError(22, 'The device does not recognize the command.'))

Exception in Tkinter callback
Traceback (most recent call last):
  File "Tkinter.pyo", line 1536, in __call__
  File "AR2.py", line 2663, in manReplItem
IndexError: tuple index out of range
Exception in thread Thread-2:
Traceback (most recent call last):
  File "threading.pyo", line 801, in __bootstrap_inner
  File "threading.pyo", line 754, in run
  File "AR2.py", line 726, in threadProg
  File "AR2.py", line 472, in executeRow
  File "AR2.py", line 3498, in MoveXYZ
  File "AR2.py", line 4108, in MoveNew
  File "AR2.py", line 1218, in savePosData
IOError: [Errno 13] Permission denied: 'ARbot.cal'

Exception in thread Thread-3:
Traceback (most recent call last):
  File "threading.pyo", line 801, in __bootstrap_inner
  File "threading.pyo", line 754, in run
  File "AR2.py", line 718, in threadProg
  File "Tkinter.pyo", line 2664, in selection_set
TclError: invalid command name "1"

Exception in Tkinter callback
Traceback (most recent call last):
  File "Tkinter.pyo", line 1536, in __call__
  File "AR2.py", line 1803, in J5jogPos
  File "AR2.py", line 1218, in savePosData
IOError: [Errno 13] Permission denied: 'ARbot.cal'
Exception in Tkinter callback
Traceback (most recent call last):
  File "Tkinter.pyo", line 1536, in __call__
  File "AR2.py", line 2092, in ZjogPos
  File "AR2.py", line 3498, in MoveXYZ
  File "AR2.py", line 4108, in MoveNew
  File "AR2.py", line 1218, in savePosData
IOError: [Errno 13] Permission denied: 'ARbot.cal'
Exception in Tkinter callback
Traceback (most recent call last):
  File "Tkinter.pyo", line 1536, in __call__
  File "AR2.py", line 2092, in ZjogPos
  File "AR2.py", line 3498, in MoveXYZ
  File "AR2.py", line 4108, in MoveNew
  File "AR2.py", line 1218, in savePosData
IOError: [Errno 13] Permission denied: 'ARbot.cal'
Exception in thread Thread-6:
Traceback (most recent call last):
  File "threading.pyo", line 801, in __bootstrap_inner
  File "threading.pyo", line 754, in run
  File "AR2.py", line 718, in threadProg
  File "Tkinter.pyo", line 2664, in selection_set
TclError: ambiguous option "": must be anchor, clear, includes, or set

Exception in Tkinter callback
Traceback (most recent call last):
  File "Tkinter.pyo", line 1536, in __call__
  File "AR2.py", line 2663, in manReplItem
IndexError: tuple index out of range
Exception in Tkinter callback
Traceback (most recent call last):
  File "Tkinter.pyo", line 1536, in __call__
  File "AR2.py", line 2558, in teachInsertBelSelected
UnboundLocalError: local variable 'selRow' referenced before assignment
Exception in Tkinter callback
Traceback (most recent call last):
  File "Tkinter.pyo", line 1536, in __call__
  File "AR2.py", line 2745, in jumpTab
IndexError: tuple index out of range
Exception in Tkinter callback
Traceback (most recent call last):
  File "Tkinter.pyo", line 1536, in __call__
  File "AR2.py", line 2298, in TZjogNeg
  File "AR2.py", line 3498, in MoveXYZ
  File "AR2.py", line 4108, in MoveNew
  File "AR2.py", line 1218, in savePosData
IOError: [Errno 13] Permission denied: 'ARbot.cal'
Exception in Tkinter callback
Traceback (most recent call last):
  File "Tkinter.pyo", line 1536, in __call__
  File "AR2.py", line 1803, in J5jogPos
  File "AR2.py", line 1218, in savePosData
IOError: [Errno 13] Permission denied: 'ARbot.cal'
Exception in Tkinter callback
Traceback (most recent call last):
  File "Tkinter.pyo", line 1536, in __call__
  File "AR2.py", line 2663, in manReplItem
IndexError: tuple index out of range
Exception in Tkinter callback
Traceback (most recent call last):
  File "Tkinter.pyo", line 1536, in __call__
  File "AR2.py", line 665, in stepFwd
  File "AR2.py", line 251, in executeRow
IndexError: tuple index out of range
Exception in Tkinter callback
Traceback (most recent call last):
  File "Tkinter.pyo", line 1536, in __call__
  File "AR2.py", line 228, in deleteitem
IndexError: tuple index out of range
Exception in Tkinter callback
Traceback (most recent call last):
  File "Tkinter.pyo", line 1536, in __call__
  File "AR2.py", line 2648, in manInsItem
IndexError: tuple index out of range
Exception in thread Thread-1:
Traceback (most recent call last):
  File "threading.pyo", line 801, in __bootstrap_inner
  File "threading.pyo", line 754, in run
  File "AR2.py", line 718, in threadProg
  File "Tkinter.pyo", line 2664, in selection_set
TclError: ambiguous option "": must be activate, bbox, cget, configure, curselection, delete, get, index, insert, itemcget, itemconfigure, nearest, scan, see, selection, size, xview, or yview

Exception in Tkinter callback
Traceback (most recent call last):
  File "Tkinter.pyo", line 1536, in __call__
  File "AR2.py", line 1957, in ZjogNeg
  File "AR2.py", line 3498, in MoveXYZ
  File "AR2.py", line 4108, in MoveNew
  File "AR2.py", line 1218, in savePosData
IOError: [Errno 13] Permission denied: 'ARbot.cal'
Exception in Tkinter callback
Traceback (most recent call last):
  File "Tkinter.pyo", line 1536, in __call__
  File "AR2.py", line 1539, in J2jogNeg
  File "AR2.py", line 1218, in savePosData
IOError: [Errno 13] Permission denied: 'ARbot.cal'
Exception in Tkinter callback
Traceback (most recent call last):
  File "Tkinter.pyo", line 1536, in __call__
  File "AR2.py", line 665, in stepFwd
  File "AR2.py", line 251, in executeRow
IndexError: tuple index out of range
Exception in Tkinter callback
Traceback (most recent call last):
  File "Tkinter.pyo", line 1536, in __call__
  File "AR2.py", line 665, in stepFwd
  File "AR2.py", line 251, in executeRow
IndexError: tuple index out of range
Exception in thread Thread-5:
Traceback (most recent call last):
  File "threading.pyo", line 801, in __bootstrap_inner
  File "threading.pyo", line 754, in run
  File "AR2.py", line 726, in threadProg
  File "AR2.py", line 251, in executeRow
IndexError: tuple index out of range

Exception in thread Thread-4:
Traceback (most recent call last):
  File "threading.pyo", line 801, in __bootstrap_inner
  File "threading.pyo", line 754, in run
  File "AR2.py", line 726, in threadProg
  File "AR2.py", line 472, in executeRow
  File "AR2.py", line 3498, in MoveXYZ
  File "AR2.py", line 4088, in MoveNew
  File "serial\serialwin32.pyo", line 322, in write
SerialTimeoutException: Write timeout

Exception in thread Thread-5:
Traceback (most recent call last):
  File "threading.pyo", line 801, in __bootstrap_inner
  File "threading.pyo", line 754, in run
  File "AR2.py", line 726, in threadProg
  File "AR2.py", line 472, in executeRow
  File "AR2.py", line 3498, in MoveXYZ
  File "AR2.py", line 4108, in MoveNew
  File "AR2.py", line 1218, in savePosData
IOError: [Errno 13] Permission denied: 'ARbot.cal'

Exception in thread Thread-6:
Traceback (most recent call last):
  File "threading.pyo", line 801, in __bootstrap_inner
  File "threading.pyo", line 754, in run
  File "AR2.py", line 726, in threadProg
  File "AR2.py", line 472, in executeRow
  File "AR2.py", line 3498, in MoveXYZ
  File "AR2.py", line 4108, in MoveNew
  File "AR2.py", line 1218, in savePosData
IOError: [Errno 13] Permission denied: 'ARbot.cal'

Exception in thread Thread-7:
Traceback (most recent call last):
  File "threading.pyo", line 801, in __bootstrap_inner
  File "threading.pyo", line 754, in run
  File "AR2.py", line 726, in threadProg
  File "AR2.py", line 472, in executeRow
  File "AR2.py", line 3498, in MoveXYZ
  File "AR2.py", line 4108, in MoveNew
  File "AR2.py", line 1218, in savePosData
IOError: [Errno 13] Permission denied: 'ARbot.cal'

Exception in thread Thread-8:
Traceback (most recent call last):
  File "threading.pyo", line 801, in __bootstrap_inner
  File "threading.pyo", line 754, in run
  File "AR2.py", line 726, in threadProg
  File "AR2.py", line 472, in executeRow
  File "AR2.py", line 3498, in MoveXYZ
  File "AR2.py", line 4108, in MoveNew
  File "AR2.py", line 1218, in savePosData
IOError: [Errno 13] Permission denied: 'ARbot.cal'

Exception in thread Thread-1:
Traceback (most recent call last):
  File "threading.pyo", line 801, in __bootstrap_inner
  File "threading.pyo", line 754, in run
  File "AR2.py", line 726, in threadProg
  File "AR2.py", line 472, in executeRow
  File "AR2.py", line 3498, in MoveXYZ
  File "AR2.py", line 4108, in MoveNew
  File "AR2.py", line 1218, in savePosData
IOError: [Errno 13] Permission denied: 'ARbot.cal'

Exception in Tkinter callback
Traceback (most recent call last):
  File "Tkinter.pyo", line 1536, in __call__
  File "AR2.py", line 665, in stepFwd
  File "AR2.py", line 251, in executeRow
IndexError: tuple index out of range
Exception in thread Thread-1:
Traceback (most recent call last):
  File "threading.pyo", line 801, in __bootstrap_inner
  File "threading.pyo", line 754, in run
  File "AR2.py", line 726, in threadProg
  File "AR2.py", line 372, in executeRow
  File "serial\serialwin32.pyo", line 322, in write
SerialTimeoutException: Write timeout

Exception in Tkinter callback
Traceback (most recent call last):
  File "Tkinter.pyo", line 1536, in __call__
  File "AR2.py", line 1457, in J1jogNeg
  File "serial\serialwin32.pyo", line 314, in write
SerialException: WriteFile failed (WindowsError(22, 'The device does not recognize the command.'))
Exception in Tkinter callback
Traceback (most recent call last):
  File "Tkinter.pyo", line 1536, in __call__
  File "AR2.py", line 1498, in J1jogPos
  File "serial\serialwin32.pyo", line 314, in write
SerialException: WriteFile failed (WindowsError(22, 'The device does not recognize the command.'))
Exception in Tkinter callback
Traceback (most recent call last):
  File "Tkinter.pyo", line 1536, in __call__
  File "AR2.py", line 1457, in J1jogNeg
  File "serial\serialwin32.pyo", line 314, in write
SerialException: WriteFile failed (WindowsError(22, 'The device does not recognize the command.'))
Exception in Tkinter callback
Traceback (most recent call last):
  File "Tkinter.pyo", line 1536, in __call__
  File "AR2.py", line 1457, in J1jogNeg
  File "serial\serialwin32.pyo", line 314, in write
SerialException: WriteFile failed (WindowsError(22, 'The device does not recognize the command.'))
Exception in Tkinter callback
Traceback (most recent call last):
  File "Tkinter.pyo", line 1536, in __call__
  File "AR2.py", line 1498, in J1jogPos
  File "serial\serialwin32.pyo", line 314, in write
SerialException: WriteFile failed (WindowsError(22, 'The device does not recognize the command.'))
Exception in thread Thread-1:
Traceback (most recent call last):
  File "threading.pyo", line 801, in __bootstrap_inner
  File "threading.pyo", line 754, in run
  File "AR2.py", line 726, in threadProg
  File "AR2.py", line 472, in executeRow
  File "AR2.py", line 3498, in MoveXYZ
  File "AR2.py", line 4088, in MoveNew
  File "serial\serialwin32.pyo", line 314, in write
SerialException: WriteFile failed (WindowsError(22, 'The device does not recognize the command.'))

Exception in thread Thread-2:
Traceback (most recent call last):
  File "threading.pyo", line 801, in __bootstrap_inner
  File "threading.pyo", line 754, in run
  File "AR2.py", line 726, in threadProg
  File "AR2.py", line 472, in executeRow
  File "AR2.py", line 3498, in MoveXYZ
  File "AR2.py", line 4088, in MoveNew
  File "serial\serialwin32.pyo", line 314, in write
SerialException: WriteFile failed (WindowsError(22, 'The device does not recognize the command.'))

Exception in Tkinter callback
Traceback (most recent call last):
  File "Tkinter.pyo", line 1536, in __call__
  File "AR2.py", line 2433, in TZjogPos
  File "AR2.py", line 3498, in MoveXYZ
  File "AR2.py", line 4108, in MoveNew
  File "AR2.py", line 1218, in savePosData
IOError: [Errno 13] Permission denied: 'ARbot.cal'
Exception in Tkinter callback
Traceback (most recent call last):
  File "Tkinter.pyo", line 1536, in __call__
  File "AR2.py", line 665, in stepFwd
  File "AR2.py", line 472, in executeRow
  File "AR2.py", line 3498, in MoveXYZ
  File "AR2.py", line 4108, in MoveNew
  File "AR2.py", line 1218, in savePosData
IOError: [Errno 13] Permission denied: 'ARbot.cal'
Exception in thread Thread-10:
Traceback (most recent call last):
  File "threading.pyo", line 801, in __bootstrap_inner
  File "threading.pyo", line 754, in run
  File "AR2.py", line 735, in threadProg
  File "Tkinter.pyo", line 2681, in itemconfigure
  File "Tkinter.pyo", line 1317, in _configure
TclError: bad listbox index "raised": must be active, anchor, end, @x,y, or a number

Exception in thread Thread-12:
Traceback (most recent call last):
  File "threading.pyo", line 801, in __bootstrap_inner
  File "threading.pyo", line 754, in run
  File "AR2.py", line 726, in threadProg
  File "AR2.py", line 472, in executeRow
  File "AR2.py", line 3498, in MoveXYZ
  File "AR2.py", line 4108, in MoveNew
  File "AR2.py", line 1218, in savePosData
IOError: [Errno 13] Permission denied: 'ARbot.cal'

Exception in thread Thread-13:
Traceback (most recent call last):
  File "threading.pyo", line 801, in __bootstrap_inner
  File "threading.pyo", line 754, in run
  File "AR2.py", line 726, in threadProg
  File "AR2.py", line 472, in executeRow
  File "AR2.py", line 3498, in MoveXYZ
  File "AR2.py", line 4108, in MoveNew
  File "AR2.py", line 1218, in savePosData
IOError: [Errno 13] Permission denied: 'ARbot.cal'

Exception in thread Thread-14:
Traceback (most recent call last):
  File "threading.pyo", line 801, in __bootstrap_inner
  File "threading.pyo", line 754, in run
  File "AR2.py", line 726, in threadProg
  File "AR2.py", line 472, in executeRow
  File "AR2.py", line 3498, in MoveXYZ
  File "AR2.py", line 4108, in MoveNew
  File "AR2.py", line 1218, in savePosData
IOError: [Errno 13] Permission denied: 'ARbot.cal'

Exception in thread Thread-15:
Traceback (most recent call last):
  File "threading.pyo", line 801, in __bootstrap_inner
  File "threading.pyo", line 754, in run
  File "AR2.py", line 726, in threadProg
  File "AR2.py", line 472, in executeRow
  File "AR2.py", line 3498, in MoveXYZ
  File "AR2.py", line 4108, in MoveNew
  File "AR2.py", line 1218, in savePosData
IOError: [Errno 13] Permission denied: 'ARbot.cal'

Exception in thread Thread-2:
Traceback (most recent call last):
  File "threading.pyo", line 801, in __bootstrap_inner
  File "threading.pyo", line 754, in run
  File "AR2.py", line 726, in threadProg
  File "AR2.py", line 472, in executeRow
  File "AR2.py", line 3498, in MoveXYZ
  File "AR2.py", line 4108, in MoveNew
  File "AR2.py", line 1218, in savePosData
IOError: [Errno 13] Permission denied: 'ARbot.cal'

Exception in Tkinter callback
Traceback (most recent call last):
  File "Tkinter.pyo", line 1536, in __call__
  File "AR2.py", line 665, in stepFwd
  File "AR2.py", line 251, in executeRow
IndexError: tuple index out of range
Exception in Tkinter callback
Traceback (most recent call last):
  File "Tkinter.pyo", line 1536, in __call__
  File "AR2.py", line 665, in stepFwd
  File "AR2.py", line 251, in executeRow
IndexError: tuple index out of range
Exception in thread Thread-3:
Traceback (most recent call last):
  File "threading.pyo", line 801, in __bootstrap_inner
  File "threading.pyo", line 754, in run
  File "AR2.py", line 726, in threadProg
  File "AR2.py", line 251, in executeRow
IndexError: tuple index out of range

Exception in Tkinter callback
Traceback (most recent call last):
  File "Tkinter.pyo", line 1536, in __call__
  File "AR2.py", line 2558, in teachInsertBelSelected
UnboundLocalError: local variable 'selRow' referenced before assignment
Exception in Tkinter callback
Traceback (most recent call last):
  File "Tkinter.pyo", line 1536, in __call__
  File "AR2.py", line 1613, in J3jogNeg
  File "AR2.py", line 1218, in savePosData
IOError: [Errno 13] Permission denied: 'ARbot.cal'
Exception in Tkinter callback
Traceback (most recent call last):
  File "Tkinter.pyo", line 1536, in __call__
  File "AR2.py", line 2663, in manReplItem
IndexError: tuple index out of range
Exception in Tkinter callback
Traceback (most recent call last):
  File "Tkinter.pyo", line 1536, in __call__
  File "AR2.py", line 665, in stepFwd
  File "AR2.py", line 251, in executeRow
IndexError: tuple index out of range
Exception in Tkinter callback
Traceback (most recent call last):
  File "Tkinter.pyo", line 1536, in __call__
  File "AR2.py", line 665, in stepFwd
  File "AR2.py", line 251, in executeRow
IndexError: tuple index out of range
Exception in Tkinter callback
Traceback (most recent call last):
  File "Tkinter.pyo", line 1536, in __call__
  File "AR2.py", line 665, in stepFwd
  File "AR2.py", line 251, in executeRow
IndexError: tuple index out of range
Exception in Tkinter callback
Traceback (most recent call last):
  File "Tkinter.pyo", line 1536, in __call__
  File "AR2.py", line 1687, in J4jogNeg
  File "AR2.py", line 1218, in savePosData
IOError: [Errno 13] Permission denied: 'ARbot.cal'
Exception in Tkinter callback
Traceback (most recent call last):
  File "Tkinter.pyo", line 1536, in __call__
  File "AR2.py", line 665, in stepFwd
  File "AR2.py", line 251, in executeRow
IndexError: tuple index out of range
Exception in Tkinter callback
Traceback (most recent call last):
  File "Tkinter.pyo", line 1536, in __call__
  File "AR2.py", line 665, in stepFwd
  File "AR2.py", line 251, in executeRow
IndexError: tuple index out of range
Exception in Tkinter callback
Traceback (most recent call last):
  File "Tkinter.pyo", line 1536, in __call__
  File "AR2.py", line 665, in stepFwd
  File "AR2.py", line 251, in executeRow
IndexError: tuple index out of range
Exception in Tkinter callback
Traceback (most recent call last):
  File "Tkinter.pyo", line 1536, in __call__
  File "AR2.py", line 665, in stepFwd
  File "AR2.py", line 251, in executeRow
IndexError: tuple index out of range
Exception in Tkinter callback
Traceback (most recent call last):
  File "Tkinter.pyo", line 1536, in __call__
  File "AR2.py", line 665, in stepFwd
  File "AR2.py", line 251, in executeRow
IndexError: tuple index out of range
Exception in Tkinter callback
Traceback (most recent call last):
  File "Tkinter.pyo", line 1536, in __call__
  File "AR2.py", line 2558, in teachInsertBelSelected
UnboundLocalError: local variable 'selRow' referenced before assignment
Exception in Tkinter callback
Traceback (most recent call last):
  File "Tkinter.pyo", line 1536, in __call__
  File "AR2.py", line 2558, in teachInsertBelSelected
UnboundLocalError: local variable 'selRow' referenced before assignment
Exception in Tkinter callback
Traceback (most recent call last):
  File "Tkinter.pyo", line 1536, in __call__
  File "AR2.py", line 665, in stepFwd
  File "AR2.py", line 251, in executeRow
IndexError: tuple index out of range
Exception in Tkinter callback
Traceback (most recent call last):
  File "Tkinter.pyo", line 1536, in __call__
  File "AR2.py", line 1803, in J5jogPos
  File "AR2.py", line 1218, in savePosData
IOError: [Errno 13] Permission denied: 'ARbot.cal'
Exception in thread Thread-1:
Traceback (most recent call last):
  File "threading.pyo", line 801, in __bootstrap_inner
  File "threading.pyo", line 754, in run
  File "AR2.py", line 726, in threadProg
  File "AR2.py", line 472, in executeRow
  File "AR2.py", line 3498, in MoveXYZ
  File "AR2.py", line 4088, in MoveNew
NameError: global name 'ser' is not defined

Exception in Tkinter callback
Traceback (most recent call last):
  File "Tkinter.pyo", line 1536, in __call__
  File "AR2.py", line 665, in stepFwd
  File "AR2.py", line 251, in executeRow
IndexError: tuple index out of range
Exception in Tkinter callback
Traceback (most recent call last):
  File "Tkinter.pyo", line 1536, in __call__
  File "AR2.py", line 1803, in J5jogPos
  File "AR2.py", line 1218, in savePosData
IOError: [Errno 13] Permission denied: 'ARbot.cal'
Exception in Tkinter callback
Traceback (most recent call last):
  File "Tkinter.pyo", line 1536, in __call__
  File "AR2.py", line 665, in stepFwd
  File "AR2.py", line 251, in executeRow
IndexError: tuple index out of range
Exception in Tkinter callback
Traceback (most recent call last):
  File "Tkinter.pyo", line 1536, in __call__
  File "AR2.py", line 665, in stepFwd
  File "AR2.py", line 251, in executeRow
IndexError: tuple index out of range
Exception in Tkinter callback
Traceback (most recent call last):
  File "Tkinter.pyo", line 1536, in __call__
  File "AR2.py", line 665, in stepFwd
  File "AR2.py", line 251, in executeRow
IndexError: tuple index out of range
Exception in Tkinter callback
Traceback (most recent call last):
  File "Tkinter.pyo", line 1536, in __call__
  File "AR2.py", line 665, in stepFwd
  File "AR2.py", line 472, in executeRow
  File "AR2.py", line 3498, in MoveXYZ
  File "AR2.py", line 4108, in MoveNew
  File "AR2.py", line 1218, in savePosData
IOError: [Errno 13] Permission denied: 'ARbot.cal'
Exception in Tkinter callback
Traceback (most recent call last):
  File "Tkinter.pyo", line 1536, in __call__
  File "AR2.py", line 665, in stepFwd
  File "AR2.py", line 251, in executeRow
IndexError: tuple index out of range
Exception in Tkinter callback
Traceback (most recent call last):
  File "Tkinter.pyo", line 1536, in __call__
  File "AR2.py", line 665, in stepFwd
  File "AR2.py", line 251, in executeRow
IndexError: tuple index out of range
Exception in thread Thread-1:
Traceback (most recent call last):
  File "threading.pyo", line 801, in __bootstrap_inner
  File "threading.pyo", line 754, in run
  File "AR2.py", line 724, in threadProg
  File "Tkinter.pyo", line 1326, in configure
  File "Tkinter.pyo", line 1317, in _configure
TclError: invalid command name "-text"

Exception in Tkinter callback
Traceback (most recent call last):
  File "Tkinter.pyo", line 1536, in __call__
  File "AR2.py", line 665, in stepFwd
  File "AR2.py", line 251, in executeRow
IndexError: tuple index out of range
Exception in Tkinter callback
Traceback (most recent call last):
  File "Tkinter.pyo", line 1536, in __call__
  File "AR2.py", line 1762, in J5jogNeg
  File "AR2.py", line 1218, in savePosData
IOError: [Errno 13] Permission denied: 'ARbot.cal'
Exception in Tkinter callback
Traceback (most recent call last):
  File "Tkinter.pyo", line 1536, in __call__
  File "AR2.py", line 665, in stepFwd
  File "AR2.py", line 251, in executeRow
IndexError: tuple index out of range
Exception in Tkinter callback
Traceback (most recent call last):
  File "Tkinter.pyo", line 1536, in __call__
  File "AR2.py", line 666, in stepFwd
IndexError: tuple index out of range
Exception in Tkinter callback
Traceback (most recent call last):
  File "Tkinter.pyo", line 1536, in __call__
  File "AR2.py", line 665, in stepFwd
  File "AR2.py", line 251, in executeRow
IndexError: tuple index out of range
Exception in Tkinter callback
Traceback (most recent call last):
  File "Tkinter.pyo", line 1536, in __call__
  File "AR2.py", line 665, in stepFwd
  File "AR2.py", line 251, in executeRow
IndexError: tuple index out of range
Exception in Tkinter callback
Traceback (most recent call last):
  File "Tkinter.pyo", line 1536, in __call__
  File "AR2.py", line 665, in stepFwd
  File "AR2.py", line 251, in executeRow
IndexError: tuple index out of range
Exception in thread Thread-6:
Traceback (most recent call last):
  File "threading.pyo", line 801, in __bootstrap_inner
  File "threading.pyo", line 754, in run
  File "AR2.py", line 726, in threadProg
  File "AR2.py", line 472, in executeRow
  File "AR2.py", line 3498, in MoveXYZ
  File "AR2.py", line 4088, in MoveNew
  File "serial\serialwin32.pyo", line 314, in write
SerialException: WriteFile failed (WindowsError(22, 'The device does not recognize the command.'))

Exception in Tkinter callback
Traceback (most recent call last):
  File "Tkinter.pyo", line 1536, in __call__
  File "AR2.py", line 665, in stepFwd
  File "AR2.py", line 472, in executeRow
  File "AR2.py", line 3498, in MoveXYZ
  File "AR2.py", line 4088, in MoveNew
  File "serial\serialwin32.pyo", line 314, in write
SerialException: WriteFile failed (WindowsError(22, 'The device does not recognize the command.'))
Exception in Tkinter callback
Traceback (most recent call last):
  File "Tkinter.pyo", line 1536, in __call__
  File "AR2.py", line 665, in stepFwd
  File "AR2.py", line 472, in executeRow
  File "AR2.py", line 3498, in MoveXYZ
  File "AR2.py", line 4088, in MoveNew
  File "serial\serialwin32.pyo", line 314, in write
SerialException: WriteFile failed (WindowsError(22, 'The device does not recognize the command.'))
Exception in Tkinter callback
Traceback (most recent call last):
  File "Tkinter.pyo", line 1536, in __call__
  File "AR2.py", line 1531, in J2jogNeg
NameError: global name 'ser' is not defined
Exception in Tkinter callback
Traceback (most recent call last):
  File "Tkinter.pyo", line 1536, in __call__
  File "AR2.py", line 1572, in J2jogPos
NameError: global name 'ser' is not defined
Exception in Tkinter callback
Traceback (most recent call last):
  File "Tkinter.pyo", line 1536, in __call__
  File "AR2.py", line 1531, in J2jogNeg
NameError: global name 'ser' is not defined
Exception in Tkinter callback
Traceback (most recent call last):
  File "Tkinter.pyo", line 1536, in __call__
  File "AR2.py", line 1646, in J3jogPos
NameError: global name 'ser' is not defined
Exception in Tkinter callback
Traceback (most recent call last):
  File "Tkinter.pyo", line 1536, in __call__
  File "AR2.py", line 1605, in J3jogNeg
NameError: global name 'ser' is not defined
Exception in Tkinter callback
Traceback (most recent call last):
  File "Tkinter.pyo", line 1536, in __call__
  File "AR2.py", line 1605, in J3jogNeg
NameError: global name 'ser' is not defined
Exception in Tkinter callback
Traceback (most recent call last):
  File "Tkinter.pyo", line 1536, in __call__
  File "AR2.py", line 1605, in J3jogNeg
NameError: global name 'ser' is not defined
Exception in Tkinter callback
Traceback (most recent call last):
  File "Tkinter.pyo", line 1536, in __call__
  File "AR2.py", line 1531, in J2jogNeg
NameError: global name 'ser' is not defined
Exception in Tkinter callback
Traceback (most recent call last):
  File "Tkinter.pyo", line 1536, in __call__
  File "AR2.py", line 1531, in J2jogNeg
NameError: global name 'ser' is not defined
Exception in Tkinter callback
Traceback (most recent call last):
  File "Tkinter.pyo", line 1536, in __call__
  File "AR2.py", line 1531, in J2jogNeg
NameError: global name 'ser' is not defined
Exception in Tkinter callback
Traceback (most recent call last):
  File "Tkinter.pyo", line 1536, in __call__
  File "AR2.py", line 1531, in J2jogNeg
NameError: global name 'ser' is not defined
Exception in Tkinter callback
Traceback (most recent call last):
  File "Tkinter.pyo", line 1536, in __call__
  File "AR2.py", line 1754, in J5jogNeg
NameError: global name 'ser' is not defined
Exception in Tkinter callback
Traceback (most recent call last):
  File "Tkinter.pyo", line 1536, in __call__
  File "AR2.py", line 1795, in J5jogPos
NameError: global name 'ser' is not defined
Exception in Tkinter callback
Traceback (most recent call last):
  File "Tkinter.pyo", line 1536, in __call__
  File "AR2.py", line 1795, in J5jogPos
NameError: global name 'ser' is not defined
Exception in Tkinter callback
Traceback (most recent call last):
  File "Tkinter.pyo", line 1536, in __call__
  File "AR2.py", line 1795, in J5jogPos
NameError: global name 'ser' is not defined
Exception in Tkinter callback
Traceback (most recent call last):
  File "Tkinter.pyo", line 1536, in __call__
  File "AR2.py", line 665, in stepFwd
  File "AR2.py", line 472, in executeRow
  File "AR2.py", line 3498, in MoveXYZ
  File "AR2.py", line 4088, in MoveNew
NameError: global name 'ser' is not defined
Exception in Tkinter callback
Traceback (most recent call last):
  File "Tkinter.pyo", line 1536, in __call__
  File "AR2.py", line 665, in stepFwd
  File "AR2.py", line 472, in executeRow
  File "AR2.py", line 3498, in MoveXYZ
  File "AR2.py", line 4088, in MoveNew
NameError: global name 'ser' is not defined
Exception in Tkinter callback
Traceback (most recent call last):
  File "Tkinter.pyo", line 1536, in __call__
  File "AR2.py", line 665, in stepFwd
  File "AR2.py", line 472, in executeRow
  File "AR2.py", line 3498, in MoveXYZ
  File "AR2.py", line 4088, in MoveNew
NameError: global name 'ser' is not defined
Exception in Tkinter callback
Traceback (most recent call last):
  File "Tkinter.pyo", line 1536, in __call__
  File "AR2.py", line 1498, in J1jogPos
NameError: global name 'ser' is not defined
Exception in Tkinter callback
Traceback (most recent call last):
  File "Tkinter.pyo", line 1536, in __call__
  File "AR2.py", line 1457, in J1jogNeg
NameError: global name 'ser' is not defined
Exception in Tkinter callback
Traceback (most recent call last):
  File "Tkinter.pyo", line 1536, in __call__
  File "AR2.py", line 1457, in J1jogNeg
NameError: global name 'ser' is not defined
Exception in Tkinter callback
Traceback (most recent call last):
  File "Tkinter.pyo", line 1536, in __call__
  File "AR2.py", line 1457, in J1jogNeg
NameError: global name 'ser' is not defined
Exception in Tkinter callback
Traceback (most recent call last):
  File "Tkinter.pyo", line 1536, in __call__
  File "AR2.py", line 1457, in J1jogNeg
NameError: global name 'ser' is not defined
Exception in Tkinter callback
Traceback (most recent call last):
  File "Tkinter.pyo", line 1536, in __call__
  File "AR2.py", line 1762, in J5jogNeg
  File "AR2.py", line 1218, in savePosData
IOError: [Errno 13] Permission denied: 'ARbot.cal'
Exception in Tkinter callback
Traceback (most recent call last):
  File "Tkinter.pyo", line 1536, in __call__
  File "AR2.py", line 665, in stepFwd
  File "AR2.py", line 251, in executeRow
IndexError: tuple index out of range
Exception in Tkinter callback
Traceback (most recent call last):
  File "Tkinter.pyo", line 1536, in __call__
  File "AR2.py", line 665, in stepFwd
  File "AR2.py", line 251, in executeRow
IndexError: tuple index out of range
Exception in Tkinter callback
Traceback (most recent call last):
  File "Tkinter.pyo", line 1536, in __call__
  File "AR2.py", line 665, in stepFwd
  File "AR2.py", line 251, in executeRow
IndexError: tuple index out of range
Exception in Tkinter callback
Traceback (most recent call last):
  File "Tkinter.pyo", line 1536, in __call__
  File "AR2.py", line 665, in stepFwd
  File "AR2.py", line 472, in executeRow
  File "AR2.py", line 3498, in MoveXYZ
  File "AR2.py", line 4108, in MoveNew
  File "AR2.py", line 1218, in savePosData
IOError: [Errno 13] Permission denied: 'ARbot.cal'
Exception in Tkinter callback
Traceback (most recent call last):
  File "Tkinter.pyo", line 1536, in __call__
  File "AR2.py", line 665, in stepFwd
  File "AR2.py", line 251, in executeRow
IndexError: tuple index out of range
Exception in Tkinter callback
Traceback (most recent call last):
  File "Tkinter.pyo", line 1536, in __call__
  File "AR2.py", line 2558, in teachInsertBelSelected
UnboundLocalError: local variable 'selRow' referenced before assignment
Exception in Tkinter callback
Traceback (most recent call last):
  File "Tkinter.pyo", line 1536, in __call__
  File "AR2.py", line 2558, in teachInsertBelSelected
UnboundLocalError: local variable 'selRow' referenced before assignment
Exception in Tkinter callback
Traceback (most recent call last):
  File "Tkinter.pyo", line 1536, in __call__
  File "AR2.py", line 2558, in teachInsertBelSelected
UnboundLocalError: local variable 'selRow' referenced before assignment
Exception in thread Thread-4:
Traceback (most recent call last):
  File "threading.pyo", line 801, in __bootstrap_inner
  File "threading.pyo", line 754, in run
  File "AR2.py", line 729, in threadProg
IndexError: tuple index out of range

Exception in Tkinter callback
Traceback (most recent call last):
  File "Tkinter.pyo", line 1536, in __call__
  File "AR2.py", line 665, in stepFwd
  File "AR2.py", line 251, in executeRow
IndexError: tuple index out of range
Exception in thread Thread-5:
Traceback (most recent call last):
  File "threading.pyo", line 801, in __bootstrap_inner
  File "threading.pyo", line 754, in run
  File "AR2.py", line 724, in threadProg
  File "Tkinter.pyo", line 1326, in configure
  File "Tkinter.pyo", line 1317, in _configure
TclError: unknown color name "PROGRAM RUNNING"

Exception in Tkinter callback
Traceback (most recent call last):
  File "Tkinter.pyo", line 1536, in __call__
  File "AR2.py", line 666, in stepFwd
IndexError: tuple index out of range
Exception in thread Thread-2:
Traceback (most recent call last):
  File "threading.pyo", line 801, in __bootstrap_inner
  File "threading.pyo", line 754, in run
  File "AR2.py", line 718, in threadProg
  File "Tkinter.pyo", line 2664, in selection_set
TclError: wrong # args: should be "set varName ?newValue?"

Exception in Tkinter callback
Traceback (most recent call last):
  File "Tkinter.pyo", line 1536, in __call__
  File "AR2.py", line 665, in stepFwd
  File "AR2.py", line 251, in executeRow
IndexError: tuple index out of range
Exception in Tkinter callback
Traceback (most recent call last):
  File "Tkinter.pyo", line 1536, in __call__
  File "AR2.py", line 1605, in J3jogNeg
NameError: global name 'ser' is not defined
Exception in Tkinter callback
Traceback (most recent call last):
  File "Tkinter.pyo", line 1536, in __call__
  File "AR2.py", line 1605, in J3jogNeg
NameError: global name 'ser' is not defined
Exception in Tkinter callback
Traceback (most recent call last):
  File "Tkinter.pyo", line 1536, in __call__
  File "AR2.py", line 1605, in J3jogNeg
NameError: global name 'ser' is not defined
Exception in Tkinter callback
Traceback (most recent call last):
  File "Tkinter.pyo", line 1536, in __call__
  File "AR2.py", line 1605, in J3jogNeg
NameError: global name 'ser' is not defined
Exception in Tkinter callback
Traceback (most recent call last):
  File "Tkinter.pyo", line 1536, in __call__
  File "AR2.py", line 1605, in J3jogNeg
NameError: global name 'ser' is not defined
Exception in Tkinter callback
Traceback (most recent call last):
  File "Tkinter.pyo", line 1536, in __call__
  File "AR2.py", line 1605, in J3jogNeg
NameError: global name 'ser' is not defined
Exception in Tkinter callback
Traceback (most recent call last):
  File "Tkinter.pyo", line 1536, in __call__
  File "AR2.py", line 1605, in J3jogNeg
NameError: global name 'ser' is not defined
Exception in Tkinter callback
Traceback (most recent call last):
  File "Tkinter.pyo", line 1536, in __call__
  File "AR2.py", line 1605, in J3jogNeg
NameError: global name 'ser' is not defined
Exception in Tkinter callback
Traceback (most recent call last):
  File "Tkinter.pyo", line 1536, in __call__
  File "AR2.py", line 1605, in J3jogNeg
NameError: global name 'ser' is not defined
Exception in Tkinter callback
Traceback (most recent call last):
  File "Tkinter.pyo", line 1536, in __call__
  File "AR2.py", line 2663, in manReplItem
IndexError: tuple index out of range
Exception in thread Thread-1:
Traceback (most recent call last):
  File "threading.pyo", line 801, in __bootstrap_inner
  File "threading.pyo", line 754, in run
  File "AR2.py", line 729, in threadProg
IndexError: tuple index out of range

Exception in Tkinter callback
Traceback (most recent call last):
  File "Tkinter.pyo", line 1536, in __call__
  File "AR2.py", line 665, in stepFwd
  File "AR2.py", line 251, in executeRow
IndexError: tuple index out of range
Exception in thread Thread-5:
Traceback (most recent call last):
  File "threading.pyo", line 801, in __bootstrap_inner
  File "threading.pyo", line 754, in run
  File "AR2.py", line 729, in threadProg
IndexError: tuple index out of range

Exception in thread Thread-6:
Traceback (most recent call last):
  File "threading.pyo", line 801, in __bootstrap_inner
  File "threading.pyo", line 754, in run
  File "AR2.py", line 726, in threadProg
  File "AR2.py", line 251, in executeRow
IndexError: tuple index out of range

Exception in thread Thread-2:
Traceback (most recent call last):
  File "threading.pyo", line 801, in __bootstrap_inner
  File "threading.pyo", line 754, in run
  File "AR2.py", line 729, in threadProg
IndexError: tuple index out of range

